Workbook

Sheet All Critical Part
A1: Item Number | B1: Item Description | C1: Mesin | D1: Min Qty | E1: Max Qty | F1: =IFERROR(__xludf.DUMMYFUNCTION("ArrayFormula(IF(LEN(A:A),if(ROW(A:A)=1,""Stok"",if(isna(vlookup(A:A,importrange(""https://docs.google.com/spreadsheets/d/1xC-uAlt1jPkVMJk3mS5BBJv2KXQQM32TIOguKnEzvGo/edit?gid=2055262123#gid=2055262123"",""Inventory Tarikan Oracle!A:D""),4,0)),0,VLOOKUP(A:"&"A,importrange(""https://docs.google.com/spreadsheets/d/1xC-uAlt1jPkVMJk3mS5BBJv2KXQQM32TIOguKnEzvGo/edit?gid=2055262123#gid=2055262123"",""Inventory Tarikan Oracle!A:D""),4,0))),))"),"Stok") -> Stok | G1: {=IF(LEN(A:A),if(ROW(A:A)=1,"Status",if(F:F<D:D,"Kurang",if(F:F=D:D,"Sama","Lebih"))),)} -> Status | H1: Aktif/Tidak | I1: Notes 1 | J1: Notes 2 | K1: {=IF(LEN(A:A),if(ROW(A:A)=1,"Rekomendasi Min Stok",if(P:P="AKTIF",Roundup((L:L/12*1)+(0.25*(L:L/12)),0),0)),)} -> Rekomendasi Min Stok | L1: {=IF(LEN(A:A),if(ROW(A:A)=1,"Rekomendasi Max Stok",if(P:P="AKTIF",Roundup(U:U,0),0)),)} -> Rekomendasi Max Stok | M1: =IFERROR(__xludf.DUMMYFUNCTION("MAP(A1:A883, B1:B883, C1:C883, LAMBDA(item, desc, mesin, IF(ROW(item)=1, ""Kategori Barang"", IF(ISBLANK(item), """", LET( text_desc, LOWER(desc), IF(REGEXMATCH(text_desc, ""inverter|valve|valv|plc|motor|pump|pompa|transducer|transmitter|sensor|contro"&"l unit|cylinder|silinder|controller|servo|driver|breaker|mcb|contactor|module|hepa|fan|blower|transformer|encoder|gearbox|thermostat|solenoid|vfd|chiller|flowmeter|pressure gauge""), ""Critical Sparepart"", IF(REGEXMATCH(text_desc, ""o-ring|oring|o ring"&"|seal|gasket|bearing|baut|nut|screw|fitting|pipe|pipa|selang|hose|cleaner|filter|lamp|lampu|fuse|belt|v-belt|cable|kabel|tape|isolasi|grease|oli|oil|elbow|tee|socket|plug|clamp|ribbon|jarum|needle|cam follow""), ""Fast Moving / Consumable"", ""General S"&"parepart"")) )))))"),"Kategori Barang") -> Kategori Barang | N1: {=MAP(M1:M883, LAMBDA(kat, IF(ROW(kat)=1, "Threshold Usia (Bulan)", IF(OR(ISBLANK(kat), kat=""), "", IF(kat="Critical Sparepart", 36, IF(kat="Fast Moving / Consumable", 18, 24)) ))))} -> Threshold Usia (Bulan) | O1: {=MAP(A1:A883, LAMBDA(item, IF(ROW(item)=1, "Tanggal Transaksi Terakhir", IF(ISBLANK(item), "", LET( tgl_pr, IFERROR(MAXIFS('Data PR'!R:R, 'Data PR'!D:D, item), DATE(2000,1,1)), tgl_spr, IFERROR(MAXIFS('Data SPR'!L:L, 'Data SPR'!C:C, item), DATE(2000,1,1)), MAX(tgl_pr, tgl_spr) )))))} -> Tanggal Transaksi Terakhir | P1: {=MAP(A1:A883, N1:N883, O1:O883, LAMBDA(item, threshold, tgl, IF(ROW(item)=1, "Status Aktif/Dead Stok", IF(ISBLANK(item), "", IF(OR(ISBLANK(tgl), tgl=DATE(2000,1,1)), "TIDAK AKTIF", IF(DATEDIF(tgl, TODAY(), "M") <= threshold, "AKTIF", "TIDAK AKTIF"))))))} -> Status Aktif/Dead Stok | Q1: {=MAP(A1:A883, LAMBDA(item, IF(ROW(item)=1, "Rate PR Setahun", IF(ISBLANK(item), "", LET( total_qty, SUMIF('Data PR'!D:D, item, 'Data PR'!F:F), tgl_raw, IFERROR(MINIFS('Data PR'!R:R, 'Data PR'!D:D, item), TODAY()), tgl_pertama, IF(tgl_raw=0, TODAY(), tgl_raw), durasi_bulan, MAX(1, IFERROR(DATEDIF(tgl_pertama, TODAY(), "M"), 1)), IF(total_qty = 0, 0, ROUND((total_qty / durasi_bulan) * 12, 0)) )))))} -> Rate PR Setahun | R1: {=MAP(A1:A883, LAMBDA(item, IF(ROW(item)=1, "Rate SPR Setahun", IF(ISBLANK(item), "", LET( total_qty, SUMIF('Data SPR'!C:C, item, 'Data SPR'!E:E), tgl_raw, IFERROR(MINIFS('Data SPR'!M:M, 'Data SPR'!C:C, item), DATE(2023,1,1)), tgl_pertama, MAX(DATE(2023,1,1), tgl_raw), durasi_bulan, MAX(1, IFERROR(DATEDIF(tgl_pertama, TODAY(), "M"), 1)), IF(total_qty = 0, 0, (total_qty / durasi_bulan) * 12) )))))} -> Rate SPR Setahun | S1: {=MAP(A1:A883, LAMBDA(item, IF(ROW(item)=1, "Total Beli 1 Tahun Terakhir", IF(ISBLANK(item), "", SUMIFS('Data PR'!F:F, 'Data PR'!D:D, item, 'Data PR'!R:R, ">="&(TODAY()-365)) ))))} -> Total Beli 1 Tahun Terakhir | T1: {=IF(LEN(A:A),if(ROW(A:A)=1,"Rata-rata Tertimbang (Bobot PR 70% + SPR 30%)",IF(R:R>0, (Q:Q * 0.7) + (R:R * 0.3), Q:Q)),)} -> Rata-rata Tertimbang (Bobot PR 70% + SPR 30%) | U1: {=MAP(A1:A883, S1:S883, T1:T883, LAMBDA(item, q, r, IF(ROW(item)=1, "Rekomendasi Max Berdasarkan Tren Per Tahun", IF(ISBLANK(item), "", IF(q > r, q, r)))))} -> Rekomendasi Max Berdasarkan Tren Per Tahun
A2: O-50834-00 | B2: Autoclave Fedegari FOF / 6 AC - P/N. GM805664 Pressure Transducer and Mouting Par Replaces CD230046 | C2: Autoclave | D2: 1 | E2: 2 | F2: =IFERROR(__xludf.DUMMYFUNCTION("""COMPUTED_VALUE"""),0.0) -> 0 | G2: Kurang | H2: Aktif | I2: Discontinue | J2: - | K2: 0 | L2: 0 | M2: =IFERROR(__xludf.DUMMYFUNCTION("""COMPUTED_VALUE"""),"Critical Sparepart") -> Critical Sparepart | N2: 36 | O2: 0 | P2: TIDAK AKTIF | Q2: 0 | R2: 0 | S2: 0 | T2: 0 | U2: 0
A3: O-52922-00 | B3: Autoclave Fedegari FOF / 6 AC - Temperaure transmitter; IPAQ-L Plus 70IPLP0001; | C3: Autoclave | D3: 1 | E3: 2 | F3: =IFERROR(__xludf.DUMMYFUNCTION("""COMPUTED_VALUE"""),0.0) -> 0 | G3: Kurang | H3: Inactive | I3: Inactive | J3: - | K3: 0 | L3: 0 | M3: =IFERROR(__xludf.DUMMYFUNCTION("""COMPUTED_VALUE"""),"Critical Sparepart") -> Critical Sparepart | N3: 36 | O3: 0 | P3: TIDAK AKTIF | Q3: 0 | R3: 0 | S3: 0 | T3: 0 | U3: 0
A4: O-18687-00 | B4: Autoclave Fedegari FVA2/A1 NB2963AT - DN10/DN16 CLAMP P/N: GM100017; ; ; | C4: Autoclave | D4: 3 | E4: 6 | F4: =IFERROR(__xludf.DUMMYFUNCTION("""COMPUTED_VALUE"""),8.0) -> 8 | G4: Lebih | H4: Aktif | I4: - | J4: - | K4: 0 | L4: 0 | M4: =IFERROR(__xludf.DUMMYFUNCTION("""COMPUTED_VALUE"""),"Fast Moving / Consumable") -> Fast Moving / Consumable | N4: 18 | O4: 45009 | P4: TIDAK AKTIF | Q4: 2 | R4: 0 | S4: 0 | T4: 2 | U4: 2
A5: O-18688-00 | B5: Autoclave Fedegari FVA2/A1 NB2963AT - DN20/DN22 CLAMP P/N: GM100067; ; ; | C5: Autoclave | D5: 3 | E5: 6 | F5: =IFERROR(__xludf.DUMMYFUNCTION("""COMPUTED_VALUE"""),3.0) -> 3 | G5: Sama | H5: Aktif | I5: - | J5: - | K5: 1 | L5: 1 | M5: =IFERROR(__xludf.DUMMYFUNCTION("""COMPUTED_VALUE"""),"Fast Moving / Consumable") -> Fast Moving / Consumable | N5: 18 | O5: 45989 | P5: AKTIF | Q5: 1 | R5: 0.54545455 | S5: 0 | T5: 0.86363636 | U5: 0.86363636
A6: O-18690-00 | B6: Autoclave Fedegari FVA2/A1 NB2963AT - DN48/DN50 CLAMP P/N: GM100049; ; ; | C6: Autoclave | D6: 3 | E6: 6 | F6: =IFERROR(__xludf.DUMMYFUNCTION("""COMPUTED_VALUE"""),5.0) -> 5 | G6: Lebih | H6: Aktif | I6: - | J6: - | K6: 0 | L6: 0 | M6: =IFERROR(__xludf.DUMMYFUNCTION("""COMPUTED_VALUE"""),"Fast Moving / Consumable") -> Fast Moving / Consumable | N6: 18 | O6: 45009 | P6: TIDAK AKTIF | Q6: 1 | R6: 0 | S6: 0 | T6: 1 | U6: 1
A7: O-18686-00 | B7: Autoclave Fedegari FVA2/A1 NB2963AT - DN6-8 CLAMP P/N: GM100029; ; ; | C7: Autoclave | D7: 3 | E7: 6 | F7: =IFERROR(__xludf.DUMMYFUNCTION("""COMPUTED_VALUE"""),3.0) -> 3 | G7: Sama | H7: Aktif | I7: - | J7: - | K7: 0 | L7: 0 | M7: =IFERROR(__xludf.DUMMYFUNCTION("""COMPUTED_VALUE"""),"Fast Moving / Consumable") -> Fast Moving / Consumable | N7: 18 | O7: 45009 | P7: TIDAK AKTIF | Q7: 1 | R7: 0 | S7: 0 | T7: 1 | U7: 1
A8: O-16731-00 | B8: Autoclave Fedegari FVA2/A1 NB2963AT - KIT Ricambi Valv. DN10 ON-OFF FEDEGARI ASIA PTE LTD P/N : KK000301 pc | C8: Autoclave | D8: 8 | E8: 16 | F8: =IFERROR(__xludf.DUMMYFUNCTION("""COMPUTED_VALUE"""),0.0) -> 0 | G8: Kurang | H8: Aktif | I8: - | J8: - | K8: 1 | L8: 8 | M8: =IFERROR(__xludf.DUMMYFUNCTION("""COMPUTED_VALUE"""),"Critical Sparepart") -> Critical Sparepart | N8: 36 | O8: 46234 | P8: AKTIF | Q8: 7 | R8: 9.2727273 | S8: 5 | T8: 7.6818182 | U8: 7.6818182
A9: O-16732-00 | B9: Autoclave Fedegari FVA2/A1 NB2963AT - KIT Ricambi Valv. DN10 ON-OFF FEDEGARI ASIA PTE LTD P/N : KS000025 pc | C9: Autoclave | D9: 4 | E9: 20 | F9: =IFERROR(__xludf.DUMMYFUNCTION("""COMPUTED_VALUE"""),3.0) -> 3 | G9: Kurang | H9: Aktif | I9: - | J9: - | K9: 3 | L9: 20 | M9: =IFERROR(__xludf.DUMMYFUNCTION("""COMPUTED_VALUE"""),"Critical Sparepart") -> Critical Sparepart | N9: 36 | O9: 46234 | P9: AKTIF | Q9: 5 | R9: 4.9090909 | S9: 20 | T9: 4.9727273 | U9: 20
A10: P-13714-00 | B10: Autoclave Fedegari FVA2/A1 NB2963AT - Oring Viton 29 x 22 x 3.5 mm; ; ; | C10: Autoclave | D10: 10 | E10: 20 | F10: =IFERROR(__xludf.DUMMYFUNCTION("""COMPUTED_VALUE"""),0.0) -> 0 | G10: Kurang | H10: Inactive | I10: Inactive | J10: - | K10: 0 | L10: 0 | M10: =IFERROR(__xludf.DUMMYFUNCTION("""COMPUTED_VALUE"""),"Fast Moving / Consumable") -> Fast Moving / Consumable | N10: 18 | O10: 45261 | P10: TIDAK AKTIF | Q10: 1 | R10: 1.3636364 | S10: 0 | T10: 1.1090909 | U10: 1.1090909
A11: O-20982-00 | B11: Autoclave FVA2/A1 - SILICONE GASKET FO-5 900X1300 | C11: Autoclave | D11: 1 | E11: 2 | F11: =IFERROR(__xludf.DUMMYFUNCTION("""COMPUTED_VALUE"""),1.0) -> 1 | G11: Sama | H11: Aktif | I11: - | J11: - | K11: 1 | L11: 1 | M11: =IFERROR(__xludf.DUMMYFUNCTION("""COMPUTED_VALUE"""),"Fast Moving / Consumable") -> Fast Moving / Consumable | N11: 18 | O11: 45960 | P11: AKTIF | Q11: 1 | R11: 0 | S11: 1 | T11: 1 | U11: 1
A12: - | B12: Autoclave Service NA2247AU - AUTODIAGNOSIS ON CLEAN STEAM LINE, Fedegari, GP400045, , , | C12: Autoclave | D12: - | E12: - | F12: =IFERROR(__xludf.DUMMYFUNCTION("""COMPUTED_VALUE"""),0.0) -> 0 | G12: Kurang | H12: - | I12: Setara | J12: Setara dengan O-53442-00 | K12: 4 | L12: 31 | M12: =IFERROR(__xludf.DUMMYFUNCTION("""COMPUTED_VALUE"""),"General Sparepart") -> General Sparepart | N12: 24 | O12: 46260 | P12: AKTIF | Q12: 0 | R12: 100.63636 | S12: 0 | T12: 30.190909 | U12: 30.190909
A13: O-18692-00 | B13: Autoclave Service NA2247AU - Blind size F1, Fedegari, , , Size F1, | C13: Autoclave | D13: 1 | E13: 3 | F13: =IFERROR(__xludf.DUMMYFUNCTION("""COMPUTED_VALUE"""),1.0) -> 1 | G13: Sama | H13: Aktif | I13: - | J13: - | K13: 0 | L13: 0 | M13: =IFERROR(__xludf.DUMMYFUNCTION("""COMPUTED_VALUE"""),"General Sparepart") -> General Sparepart | N13: 24 | O13: 45009 | P13: TIDAK AKTIF | Q13: 1 | R13: 0 | S13: 0 | T13: 1 | U13: 1
A14: O-18693-00 | B14: Autoclave Service NA2247AU - Blind size F2, Fedegari, , , Size F2, | C14: Autoclave | D14: 1 | E14: 3 | F14: =IFERROR(__xludf.DUMMYFUNCTION("""COMPUTED_VALUE"""),3.0) -> 3 | G14: Lebih | H14: Aktif | I14: - | J14: - | K14: 0 | L14: 0 | M14: =IFERROR(__xludf.DUMMYFUNCTION("""COMPUTED_VALUE"""),"General Sparepart") -> General Sparepart | N14: 24 | O14: 45009 | P14: TIDAK AKTIF | Q14: 1 | R14: 0 | S14: 0 | T14: 1 | U14: 1
A15: O-18694-00 | B15: Autoclave Service NA2247AU - Blind size F3, Fedegari, , , Size F3, | C15: Autoclave | D15: 1 | E15: 3 | F15: =IFERROR(__xludf.DUMMYFUNCTION("""COMPUTED_VALUE"""),2.0) -> 2 | G15: Lebih | H15: Aktif | I15: - | J15: - | K15: 0 | L15: 0 | M15: =IFERROR(__xludf.DUMMYFUNCTION("""COMPUTED_VALUE"""),"General Sparepart") -> General Sparepart | N15: 24 | O15: 45009 | P15: TIDAK AKTIF | Q15: 1 | R15: 0 | S15: 0 | T15: 1 | U15: 1
A16: O-21124-00 | B16: Autoclave Service NA2247AU - O ring 15.47x3.53 | C16: Autoclave | D16: 5 | E16: 10 | F16: =IFERROR(__xludf.DUMMYFUNCTION("""COMPUTED_VALUE"""),5.0) -> 5 | G16: Sama | H16: Aktif | I16: Setara | J16: Setara dengan O-15918-00 | K16: 1 | L16: 6 | M16: =IFERROR(__xludf.DUMMYFUNCTION("""COMPUTED_VALUE"""),"Fast Moving / Consumable") -> Fast Moving / Consumable | N16: 18 | O16: 45960 | P16: AKTIF | Q16: 6 | R16: 0 | S16: 5 | T16: 6 | U16: 6
A17: O-21125-00 | B17: Autoclave Service NA2247AU - O ring 34.52x3.53 | C17: Autoclave | D17: 5 | E17: 10 | F17: =IFERROR(__xludf.DUMMYFUNCTION("""COMPUTED_VALUE"""),5.0) -> 5 | G17: Sama | H17: Aktif | I17: Setara | J17: Setara dengan O-15914-00 | K17: 1 | L17: 6 | M17: =IFERROR(__xludf.DUMMYFUNCTION("""COMPUTED_VALUE"""),"Fast Moving / Consumable") -> Fast Moving / Consumable | N17: 18 | O17: 45960 | P17: AKTIF | Q17: 6 | R17: 0 | S17: 5 | T17: 6 | U17: 6
A18: O-53442-00 | B18: Autoclave Service NA2247AU - Pressure Switch Alco Controls PS3-AJR 0.8-1 bar Assy | C18: Autoclave | D18: 1 | E18: 2 | F18: =IFERROR(__xludf.DUMMYFUNCTION("""COMPUTED_VALUE"""),1.0) -> 1 | G18: Sama | H18: Aktif | I18: - | J18: - | K18: 1 | L18: 1 | M18: =IFERROR(__xludf.DUMMYFUNCTION("""COMPUTED_VALUE"""),"General Sparepart") -> General Sparepart | N18: 24 | O18: 45960 | P18: AKTIF | Q18: 1 | R18: 0 | S18: 1 | T18: 1 | U18: 1
A19: O-53441-00 | B19: Autoclave Service NA2247AU - Pressure Transducer MOD. PBMH 24 | C19: Autoclave | D19: 1 | E19: 2 | F19: =IFERROR(__xludf.DUMMYFUNCTION("""COMPUTED_VALUE"""),1.0) -> 1 | G19: Sama | H19: Aktif | I19: - | J19: - | K19: 1 | L19: 1 | M19: =IFERROR(__xludf.DUMMYFUNCTION("""COMPUTED_VALUE"""),"Critical Sparepart") -> Critical Sparepart | N19: 36 | O19: 45960 | P19: AKTIF | Q19: 1 | R19: 0 | S19: 1 | T19: 1 | U19: 1
A20: O-15917-00 | B20: Fedegari FVA2/A1 - CENTERING RING DN16 CLAMP; Code : PP100907; ; ; | C20: Autoclave | D20: 1 | E20: 1 | F20: =IFERROR(__xludf.DUMMYFUNCTION("""COMPUTED_VALUE"""),3.0) -> 3 | G20: Lebih | H20: Aktif | I20: - | J20: - | K20: 0 | L20: 0 | M20: =IFERROR(__xludf.DUMMYFUNCTION("""COMPUTED_VALUE"""),"Fast Moving / Consumable") -> Fast Moving / Consumable | N20: 18 | O20: 43153 | P20: TIDAK AKTIF | Q20: 1 | R20: 0 | S20: 0 | T20: 1 | U20: 1
A21: O-15913-00 | B21: Fedegari FVA2/A1 - CENTERING RING DN35 CLAMP; Code : PP100897; ; ; | C21: Autoclave | D21: 1 | E21: 2 | F21: =IFERROR(__xludf.DUMMYFUNCTION("""COMPUTED_VALUE"""),1.0) -> 1 | G21: Sama | H21: Aktif | I21: - | J21: - | K21: 0 | L21: 0 | M21: =IFERROR(__xludf.DUMMYFUNCTION("""COMPUTED_VALUE"""),"Fast Moving / Consumable") -> Fast Moving / Consumable | N21: 18 | O21: 43153 | P21: TIDAK AKTIF | Q21: 1 | R21: 0 | S21: 0 | T21: 1 | U21: 1
A22: O-15916-00 | B22: Fedegari FVA2/A1 - CLAMP DN10 1/2" (MICROCASTED); Code : GM100017; ; ; | C22: Autoclave | D22: 1 | E22: 1 | F22: =IFERROR(__xludf.DUMMYFUNCTION("""COMPUTED_VALUE"""),1.0) -> 1 | G22: Sama | H22: Aktif | I22: - | J22: - | K22: 0 | L22: 0 | M22: =IFERROR(__xludf.DUMMYFUNCTION("""COMPUTED_VALUE"""),"Fast Moving / Consumable") -> Fast Moving / Consumable | N22: 18 | O22: 43153 | P22: TIDAK AKTIF | Q22: 0 | R22: 0 | S22: 0 | T22: 0 | U22: 0
A23: O-15912-00 | B23: Fedegari FVA2/A1 - CLAMP DN34-DN35 (MICROCASTED); Code : GM100094; ; ; | C23: Autoclave | D23: 1 | E23: 2 | F23: =IFERROR(__xludf.DUMMYFUNCTION("""COMPUTED_VALUE"""),2.0) -> 2 | G23: Lebih | H23: Aktif | I23: - | J23: - | K23: 1 | L23: 2 | M23: =IFERROR(__xludf.DUMMYFUNCTION("""COMPUTED_VALUE"""),"Fast Moving / Consumable") -> Fast Moving / Consumable | N23: 18 | O23: 46085 | P23: AKTIF | Q23: 1 | R23: 0.27272727 | S23: 2 | T23: 0.78181818 | U23: 2
A24: O-15915-00 | B24: Fedegari FVA2/A1 - DN16 ASTM CAP; Code : PM102747; ; ; | C24: Autoclave | D24: 1 | E24: 1 | F24: =IFERROR(__xludf.DUMMYFUNCTION("""COMPUTED_VALUE"""),1.0) -> 1 | G24: Sama | H24: Aktif | I24: - | J24: - | K24: 0 | L24: 0 | M24: =IFERROR(__xludf.DUMMYFUNCTION("""COMPUTED_VALUE"""),"General Sparepart") -> General Sparepart | N24: 24 | O24: 45762 | P24: AKTIF | Q24: 0 | R24: 0 | S24: 0 | T24: 0 | U24: 0
A25: O-15918-00 | B25: Fedegari FVA2/A1 - O-RING 15.47x3.53 ; Code : CC150170; ; ; | C25: Autoclave | D25: 10 | E25: 20 | F25: =IFERROR(__xludf.DUMMYFUNCTION("""COMPUTED_VALUE"""),17.0) -> 17 | G25: Lebih | H25: Aktif | I25: - | J25: - | K25: 1 | L25: 3 | M25: =IFERROR(__xludf.DUMMYFUNCTION("""COMPUTED_VALUE"""),"Fast Moving / Consumable") -> Fast Moving / Consumable | N25: 18 | O25: 46234 | P25: AKTIF | Q25: 3 | R25: 1.3636364 | S25: 0 | T25: 2.5090909 | U25: 2.5090909
A26: O-15914-00 | B26: Fedegari FVA2/A1 - O-RING 34.52x3.53; Code : CC150171; ; ; | C26: Autoclave | D26: 10 | E26: 20 | F26: =IFERROR(__xludf.DUMMYFUNCTION("""COMPUTED_VALUE"""),15.0) -> 15 | G26: Lebih | H26: Aktif | I26: - | J26: - | K26: 1 | L26: 3 | M26: =IFERROR(__xludf.DUMMYFUNCTION("""COMPUTED_VALUE"""),"Fast Moving / Consumable") -> Fast Moving / Consumable | N26: 18 | O26: 46022 | P26: AKTIF | Q26: 3 | R26: 1.3636364 | S26: 0 | T26: 2.5090909 | U26: 2.5090909
A27: O-15911-00 | B27: Fedegari FVA2/A1 - TAPPO DN35 ASTM; Code : PM102749; ; ; | C27: Autoclave | D27: 4 | E27: 8 | F27: =IFERROR(__xludf.DUMMYFUNCTION("""COMPUTED_VALUE"""),5.0) -> 5 | G27: Lebih | H27: Aktif | I27: - | J27: - | K27: 0 | L27: 0 | M27: =IFERROR(__xludf.DUMMYFUNCTION("""COMPUTED_VALUE"""),"General Sparepart") -> General Sparepart | N27: 24 | O27: 45009 | P27: TIDAK AKTIF | Q27: 1 | R27: 0 | S27: 0 | T27: 1 | U27: 1
A28: P-15429-00 | B28: Fedegari FVA2/A1 S/N : NB2964AT - Cover Seal FVM-A/2 FOB2 (Code: PP600265); ; ; | C28: Autoclave | D28: 1 | E28: 4 | F28: =IFERROR(__xludf.DUMMYFUNCTION("""COMPUTED_VALUE"""),4.0) -> 4 | G28: Lebih | H28: Aktif | I28: - | J28: - | K28: 1 | L28: 2 | M28: =IFERROR(__xludf.DUMMYFUNCTION("""COMPUTED_VALUE"""),"Fast Moving / Consumable") -> Fast Moving / Consumable | N28: 18 | O28: 46043 | P28: AKTIF | Q28: 1 | R28: 0.54545455 | S28: 2 | T28: 0.86363636 | U28: 2
A29: O-17831-00 | B29: Gear Door Autoclave | C29: Autoclave | D29: 1 | E29: 2 | F29: =IFERROR(__xludf.DUMMYFUNCTION("""COMPUTED_VALUE"""),1.0) -> 1 | G29: Sama | H29: Aktif | I29: - | J29: - | K29: 1 | L29: 1 | M29: =IFERROR(__xludf.DUMMYFUNCTION("""COMPUTED_VALUE"""),"General Sparepart") -> General Sparepart | N29: 24 | O29: 46112 | P29: AKTIF | Q29: 1 | R29: 0.27272727 | S29: 0 | T29: 0.78181818 | U29: 0.78181818
A30: P-17361-00 | B30: O-ring EPDM 15 x 9 x 3 mm ; Brand : - ; P/N : - ; Pack Size : pcs | C30: Autoclave | D30: 10 | E30: 20 | F30: =IFERROR(__xludf.DUMMYFUNCTION("""COMPUTED_VALUE"""),20.0) -> 20 | G30: Lebih | H30: Aktif | I30: - | J30: - | K30: 2 | L30: 13 | M30: =IFERROR(__xludf.DUMMYFUNCTION("""COMPUTED_VALUE"""),"Fast Moving / Consumable") -> Fast Moving / Consumable | N30: 18 | O30: 46147 | P30: AKTIF | Q30: 7 | R30: 5.1818182 | S30: 13 | T30: 6.4545455 | U30: 13
A31: P-17359-00 | B31: O-ring EPDM 41.5 x 35 x 3.5 mm ; Brand : - ; P/N : - ; Pack Size : pcs | C31: Autoclave | D31: 10 | E31: 20 | F31: =IFERROR(__xludf.DUMMYFUNCTION("""COMPUTED_VALUE"""),19.0) -> 19 | G31: Lebih | H31: Aktif | I31: - | J31: - | K31: 1 | L31: 4 | M31: =IFERROR(__xludf.DUMMYFUNCTION("""COMPUTED_VALUE"""),"Fast Moving / Consumable") -> Fast Moving / Consumable | N31: 18 | O31: 45863 | P31: AKTIF | Q31: 5 | R31: 0.27272727 | S31: 0 | T31: 3.5818182 | U31: 3.5818182
A32: P-17272-00 | B32: O-ring Epdm 9 x 4 x 2,5 mm ; Brand : - ; P/N : - ; Pack Size : pcs | C32: Autoclave | D32: 10 | E32: 20 | F32: =IFERROR(__xludf.DUMMYFUNCTION("""COMPUTED_VALUE"""),64.0) -> 64 | G32: Lebih | H32: Aktif | I32: - | J32: - | K32: 2 | L32: 16 | M32: =IFERROR(__xludf.DUMMYFUNCTION("""COMPUTED_VALUE"""),"Fast Moving / Consumable") -> Fast Moving / Consumable | N32: 18 | O32: 45989 | P32: AKTIF | Q32: 21 | R32: 1.6363636 | S32: 0 | T32: 15.190909 | U32: 15.190909
A33: P-17273-00 | B33: O-ring Epdm 9 x 5 x 2 mm ; Brand : - ; P/N : - ; Pack Size : pcs | C33: Autoclave | D33: 10 | E33: 20 | F33: =IFERROR(__xludf.DUMMYFUNCTION("""COMPUTED_VALUE"""),13.0) -> 13 | G33: Lebih | H33: Aktif | I33: - | J33: - | K33: 1 | L33: 5 | M33: =IFERROR(__xludf.DUMMYFUNCTION("""COMPUTED_VALUE"""),"Fast Moving / Consumable") -> Fast Moving / Consumable | N33: 18 | O33: 45989 | P33: AKTIF | Q33: 6 | R33: 2.4545455 | S33: 0 | T33: 4.9363636 | U33: 4.9363636
A34: O-19339-00 | B34: Oring 2,5x6x11 mm, Material EPDM; ; ; | C34: Autoclave | D34: 10 | E34: 21 | F34: =IFERROR(__xludf.DUMMYFUNCTION("""COMPUTED_VALUE"""),19.0) -> 19 | G34: Lebih | H34: Aktif | I34: - | J34: - | K34: 2 | L34: 12 | M34: =IFERROR(__xludf.DUMMYFUNCTION("""COMPUTED_VALUE"""),"Fast Moving / Consumable") -> Fast Moving / Consumable | N34: 18 | O34: 45989 | P34: AKTIF | Q34: 14 | R34: 4.3636364 | S34: 0 | T34: 11.109091 | U34: 11.109091
A35: O-51743-00 | B35: SENSOR TEMPERATUR PT100 7 METER 4 WIRE; PART NO :PM600083 | C35: Autoclave | D35: 1 | E35: 2 | F35: =IFERROR(__xludf.DUMMYFUNCTION("""COMPUTED_VALUE"""),0.0) -> 0 | G35: Kurang | H35: Inactive | I35: Setara | J35: Setara dengan O-52278-00 | K35: 0 | L35: 0 | M35: =IFERROR(__xludf.DUMMYFUNCTION("""COMPUTED_VALUE"""),"Critical Sparepart") -> Critical Sparepart | N35: 36 | O35: 0 | P35: TIDAK AKTIF | Q35: 0 | R35: 0 | S35: 0 | T35: 0 | U35: 0
A36: O-51747-00 | B36: TEMPERATURE PROBE ;PRODUCT ; TE2/TE2R ; | C36: Autoclave | D36: 1 | E36: 2 | F36: =IFERROR(__xludf.DUMMYFUNCTION("""COMPUTED_VALUE"""),0.0) -> 0 | G36: Kurang | H36: Inactive | I36: Setara | J36: Pake Radix O-51920-00 | K36: 0 | L36: 0 | M36: =IFERROR(__xludf.DUMMYFUNCTION("""COMPUTED_VALUE"""),"General Sparepart") -> General Sparepart | N36: 24 | O36: 0 | P36: TIDAK AKTIF | Q36: 0 | R36: 0 | S36: 0 | T36: 0 | U36: 0
A37: O-51920-00 | B37: Temperature sensor PT100, 4 wire, class AA, Duplex, c/w 10m silicon cable Radix RAC241-D-10-PN; ; ; | C37: Autoclave | D37: 1 | E37: 6 | F37: =IFERROR(__xludf.DUMMYFUNCTION("""COMPUTED_VALUE"""),0.0) -> 0 | G37: Kurang | H37: Aktif | I37: Setara | J37: Setara dengan O-53568-00 | K37: 1 | L37: 1 | M37: =IFERROR(__xludf.DUMMYFUNCTION("""COMPUTED_VALUE"""),"Critical Sparepart") -> Critical Sparepart | N37: 36 | O37: 46022 | P37: AKTIF | Q37: 1 | R37: 0.81818182 | S37: 0 | T37: 0.94545455 | U37: 0.94545455
A38: O-53414-00 | B38: Fedegari FVA2/A1 - Transition joint RTD Sensor PT100 4Wire, Sx, 1/3 DIN, 5x70mm, SSL, 0-150 C 10M; Radix; RTJ201-1-C-S-3-0-NA-XNA-05-0070-10-Si-PN; 1 Pc | C38: Autoclave | D38: 2 | E38: 8 | F38: =IFERROR(__xludf.DUMMYFUNCTION("""COMPUTED_VALUE"""),0.0) -> 0 | G38: Kurang | H38: Aktif | I38: - | J38: GL2505051 | K38: 1 | L38: 7 | M38: =IFERROR(__xludf.DUMMYFUNCTION("""COMPUTED_VALUE"""),"Critical Sparepart") -> Critical Sparepart | N38: 36 | O38: 46260 | P38: AKTIF | Q38: 8 | R38: 1.0909091 | S38: 7 | T38: 5.9272727 | U38: 7
A39: P-10564-00 | B39: Bearing 6000 2RS H SKF | C39: Capping | D39: 10 | E39: 30 | F39: =IFERROR(__xludf.DUMMYFUNCTION("""COMPUTED_VALUE"""),40.0) -> 40 | G39: Lebih | H39: Aktif | I39: - | J39: 121703198 - APPROVED | K39: 1 | L39: 7 | M39: =IFERROR(__xludf.DUMMYFUNCTION("""COMPUTED_VALUE"""),"Fast Moving / Consumable") -> Fast Moving / Consumable | N39: 18 | O39: 45909 | P39: AKTIF | Q39: 9 | R39: 0.54545455 | S39: 0 | T39: 6.4636364 | U39: 6.4636364
A40: O-11181-00 | B40: Bearing 626-2Z | C40: Capping | D40: 10 | E40: 32 | F40: =IFERROR(__xludf.DUMMYFUNCTION("""COMPUTED_VALUE"""),110.0) -> 110 | G40: Lebih | H40: Aktif | I40: - | J40: - | K40: 3 | L40: 26 | M40: =IFERROR(__xludf.DUMMYFUNCTION("""COMPUTED_VALUE"""),"Fast Moving / Consumable") -> Fast Moving / Consumable | N40: 18 | O40: 46171 | P40: AKTIF | Q40: 26 | R40: 24.545455 | S40: 0 | T40: 25.563636 | U40: 25.563636
...

Sheet MPP Fast Moving Critical & Expe
A1: O-16033-00 atau O-20487-00 Glove cRABS
A2: Tahun | B2: 2026 | G2: 2027
A3: Bulan | B3: Agu | C3: Sep | D3: Okt | E3: Nov | F3: Des | G3: Jan | H3: Feb | I3: Mar | J3: Apr | K3: Mei | L3: Jun | M3: Jul | N3: Agu | O3: Sep | P3: Okt | Q3: Nov | R3: Des
A4: Stok Awal | B4: 47 | C4: =B8 -> 35 | D4: =C8 -> 30 | E4: =D8 -> 25 | F4: =E8 -> 25 | G4: =F8 -> 25 | H4: =G8 -> 20 | I4: =H8 -> 15 | J4: =I8 -> 10 | ... R4: =Q8 -> 70
A5: Pemakaian Per Bulan | B5: 12 | C5: 5 | D5: 5 | E5: 0 | F5: 0 | G5: 5 | H5: 5 | I5: 5 | J5: 5 | K5: 5 | L5: 5 | M5: 5 | N5: 5 | O5: 5 | P5: 5 | Q5: 5 | R5: 5
A6: PR | B6: 60 | C6: 0 | D6: 0 | E6: 0 | F6: 0 | G6: 0 | H6: 40 | I6: 0 | J6: 0 | K6: 0 | L6: 0 | M6: 0 | N6: 0 | O6: 0 | P6: 0 | Q6: 0 | R6: 40
A7: Kedatangan | B7: 0 | C7: 0 | D7: 0 | E7: 0 | F7: 0 | G7: 0 | H7: 0 | I7: 0 | J7: 60 | K7: 0 | L7: 0 | M7: 0 | N7: 0 | O7: 0 | P7: 40 | Q7: 0 | R7: 0
A8: Stok Akhir | B8: =B4-B5+B7 -> 35 | C8: =C4-C5+C7 -> 30 | D8: =D4-D5+D7 -> 25 | E8: =E4-E5+E7 -> 25 | F8: =F4-F5+F7 -> 25 | G8: =G4-G5+G7 -> 20 | H8: =H4-H5+H7 -> 15 | I8: =I4-I5+I7 -> 10 | ... R8: =R4-R5+R7 -> 65
A10: O-21720-00 General - Sleeves CSM 001642 M200/90 Y 550 E4 Bt5/5 Thikness 4/10; Piercan; SP010822; 1 Pc
A11: Tahun | B11: 2026 | G11: 2027
A12: Bulan | B12: Agu | C12: Sep | D12: Okt | E12: Nov | F12: Des | G12: Jan | H12: Feb | I12: Mar | J12: Apr | K12: Mei | L12: Jun | M12: Jul | N12: Agu | O12: Sep | P12: Okt | Q12: Nov | R12: Des
A13: Stok Awal | B13: 20 | C13: =B17 -> 14 | D13: =C17 -> 11 | E13: =D17 -> 8 | F13: =E17 -> 8 | G13: =F17 -> 8 | H13: =G17 -> 5 | I13: =H17 -> 2 | J13: =I17 -> -1 | ... R13: =Q17 -> 23
A14: Pemakaian Per Bulan | B14: 6 | C14: 3 | D14: 3 | E14: 0 | F14: 0 | G14: 3 | H14: 3 | I14: 3 | J14: 3 | K14: 3 | L14: 3 | M14: 3 | N14: 3 | O14: 3 | P14: 3 | Q14: 3 | R14: 3
A15: PR | B15: 48 | C15: 0 | D15: 0 | E15: 0 | F15: 0 | G15: 0 | H15: 0 | I15: 0 | J15: 0 | K15: 24 | L15: 0 | M15: 0 | N15: 0 | O15: 0 | P15: 0 | Q15: 0 | R15: 0
A16: Kedatangan | B16: 0 | C16: 0 | D16: 0 | E16: 0 | F16: 0 | G16: 0 | H16: 0 | I16: 0 | J16: 48 | K16: 0 | L16: 0 | M16: 0 | N16: 0 | O16: 0 | P16: 0 | Q16: 0 | R16: 0
A17: Stok Akhir | B17: =B13-B14+B16 -> 14 | C17: =C13-C14+C16 -> 11 | D17: =D13-D14+D16 -> 8 | E17: =E13-E14+E16 -> 8 | F17: =F13-F14+F16 -> 8 | G17: =G13-G14+G16 -> 5 | H17: =H13-H14+H16 -> 2 | I17: =I13-I14+I16 -> -1 | ... R17: =R13-R14+R16 -> 20
A19: O-16030-00 General - Dry box glove, 4/10 mm, CSM, 97800 Y 8.5 E4 5; Piercan; 1292; 10 pcs per pack
A20: Tahun | B20: 2026 | G20: 2027
A21: Bulan | B21: Agu | C21: Sep | D21: Okt | E21: Nov | F21: Des | G21: Jan | H21: Feb | I21: Mar | J21: Apr | K21: Mei | L21: Jun | M21: Jul | N21: Agu | O21: Sep | P21: Okt | Q21: Nov | R21: Des
A22: Stok Awal | B22: 29 | C22: =B26 -> 29 | D22: =C26 -> 28 | E22: =D26 -> 47 | F22: =E26 -> 47 | G22: =F26 -> 47 | H22: =G26 -> 46 | I22: =H26 -> 45 | J22: =I26 -> 44 | ... R22: =Q26 -> 36
A23: Pemakaian Per Bulan | B23: 0 | C23: 1 | D23: 1 | E23: 0 | F23: 0 | G23: 1 | H23: 1 | I23: 1 | J23: 1 | K23: 1 | L23: 1 | M23: 1 | N23: 1 | O23: 1 | P23: 1 | Q23: 1 | R23: 1
A24: PR | B24: 0 | C24: 0 | D24: 0 | E24: 0 | F24: 0 | G24: 0 | H24: 0 | I24: 0 | J24: 0 | K24: 0 | L24: 0 | M24: 0 | N24: 0 | O24: 0 | P24: 0 | Q24: 0 | R24: 10
A25: Kedatangan | B25: 0 | C25: 0 | D25: 20 | E25: 0 | F25: 0 | G25: 0 | H25: 0 | I25: 0 | J25: 0 | K25: 0 | L25: 0 | M25: 0 | N25: 0 | O25: 0 | P25: 0 | Q25: 0 | R25: 0
A26: Stok Akhir | B26: =B22-B23+B25 -> 29 | C26: =C22-C23+C25 -> 28 | D26: =D22-D23+D25 -> 47 | E26: =E22-E23+E25 -> 47 | F26: =F22-F23+F25 -> 47 | G26: =G22-G23+G25 -> 46 | H26: =H22-H23+H25 -> 45 | I26: =I22-I23+I25 -> 44 | ... R26: =R22-R23+R25 -> 35
A28: O-21284-00 General - Isolator Gloves 000080 E10330 CNS 7 E3 5 Neoprene No Staining; Piercan; SG010138; 1 Pc
A29: Tahun | B29: 2026 | G29: 2027
A30: Bulan | B30: Agu | C30: Sep | D30: Okt | E30: Nov | F30: Des | G30: Jan | H30: Feb | I30: Mar | J30: Apr | K30: Mei | L30: Jun | M30: Jul | N30: Agu | O30: Sep | P30: Okt | Q30: Nov | R30: Des
A31: Stok Awal | B31: 30 | C31: =B35 -> 23 | D31: =C35 -> 21 | E31: =D35 -> 19 | F31: =E35 -> 17 | G31: =F35 -> 15 | H31: =G35 -> 13 | I31: =H35 -> 11 | J31: =I35 -> 19 | ... R31: =Q35 -> 13
A32: Pemakaian Per Bulan | B32: 7 | C32: 2 | D32: 2 | E32: 2 | F32: 2 | G32: 2 | H32: 2 | I32: 2 | J32: 2 | K32: 2 | L32: 2 | M32: 2 | N32: 2 | O32: 2 | P32: 2 | Q32: 2 | R32: 2
A33: PR | B33: 0 | C33: 0 | D33: 10 | E33: 0 | F33: 0 | G33: 0 | H33: 0 | I33: 0 | J33: 10 | K33: 0 | L33: 0 | M33: 0 | N33: 0 | O33: 0 | P33: 10 | Q33: 0 | R33: 0
A34: Kedatangan | B34: 0 | C34: 0 | D34: 0 | E34: 0 | F34: 0 | G34: 0 | H34: 0 | I34: 10 | J34: 0 | K34: 0 | L34: 0 | M34: 0 | N34: 0 | O34: 10 | P34: 0 | Q34: 0 | R34: 0
A35: Stok Akhir | B35: =B31-B32+B34 -> 23 | C35: =C31-C32+C34 -> 21 | D35: =D31-D32+D34 -> 19 | E35: =E31-E32+E34 -> 17 | F35: =F31-F32+F34 -> 15 | G35: =G31-G32+G34 -> 13 | H35: =H31-H32+H34 -> 11 | I35: =I31-I32+I34 -> 19 | ... R35: =R31-R32+R34 -> 11
A37: O-21485-00 General - Isolator Glove CSM Port size 8 Inch Length : 800 mm, Thick : 15mil/0.4mm; TRON; 8Y1532A0975; 1 Pc
A38: Tahun | B38: 2026 | G38: 2027
A39: Bulan | B39: Agu | C39: Sep | D39: Okt | E39: Nov | F39: Des | G39: Jan | H39: Feb | I39: Mar | J39: Apr | K39: Mei | L39: Jun | M39: Jul | N39: Agu | O39: Sep | P39: Okt | Q39: Nov | R39: Des
A40: Stok Awal | B40: 15 | C40: =B44 -> 15 | D40: =C44 -> 13 | E40: =D44 -> 11 | F40: =E44 -> 9 | G40: =F44 -> 27 | H40: =G44 -> 25 | I40: =H44 -> 23 | J40: =I44 -> 21 | ... R40: =Q44 -> 15
A41: Pemakaian Per Bulan | B41: 0 | C41: 2 | D41: 2 | E41: 2 | F41: 2 | G41: 2 | H41: 2 | I41: 2 | J41: 2 | K41: 2 | L41: 2 | M41: 2 | N41: 2 | O41: 2 | P41: 2 | Q41: 2 | R41: 2
A42: PR | B42: 20 | C42: 0 | D42: 0 | E42: 0 | F42: 0 | G42: 0 | H42: 0 | I42: 0 | J42: 10 | K42: 0 | L42: 0 | M42: 0 | N42: 10 | O42: 0 | P42: 0 | Q42: 0 | R42: 10
A43: Kedatangan | B43: 0 | C43: 0 | D43: 0 | E43: 0 | F43: 20 | G43: 0 | H43: 0 | I43: 0 | J43: 0 | K43: 0 | L43: 0 | M43: 0 | N43: 10 | O43: 0 | P43: 0 | Q43: 0 | R43: 10
A44: Total | B44: =B40-B41+B43 -> 15 | C44: =C40-C41+C43 -> 13 | D44: =D40-D41+D43 -> 11 | E44: =E40-E41+E43 -> 9 | F44: =F40-F41+F43 -> 27 | G44: =G40-G41+G43 -> 25 | H44: =H40-H41+H43 -> 23 | I44: =I40-I41+I43 -> 21 | ... R44: =R40-R41+R43 -> 23
...

Sheet Sheet2
A1: No | B1: Mesin | C1: Total Critical Part | D1: Tidak Perlu di Stok (Part setara dengan yang lain, Jarang rusak, serta mahal) | E1: Perlu Di Stok | J1: Persentase Sudah Ada | K1: Sudah Terproses | L1: Penawaran Sudah Diterima | M1: FU By Fadhil | O1: P2 | P1: P3 | Q1: Target Terproses 100% | R1: Target Stok 100%
E2: Ada Stok | F2: Tidak Ada Stok
F3: Menunggu Barang Datang | G3: Sudah Ada Item Code | H3: Belum Ada Item Code
H4: Ready Minta Penawaran | I4: Butuh Konfirmasi
A5: 1 | B5: Autoclave | C5: =countif('All Critical Part'!C:C,B5) -> 47 | D5: 11 | E5: 24 | F5: 4 | G5: 6 | H5: 1 | I5: 0 | J5: =E5/(C5-D5) -> 0.66666667 | K5: =(E5+F5)/(C5-D5) -> 0.77777778 | L5: 0 | M5: =sum(G5:I5) -> 7 | N5: =M5/(C5-D5) -> 0.19444444 | O5: 1 | P5: 0 | Q5: 46016 | R5: 45714 | S5: Persentase yang sudah terproses dari 9 mesin | T5: =sum(C5:C55) -> 690
A6: 2 | B6: Capping | C6: =countif('All Critical Part'!C:C,B6) -> 49 | D6: 20 | E6: 22 | F6: 4 | G6: 2 | H6: 1 | I6: 0 | J6: =E6/(C6-D6) -> 0.75862069 | K6: =(E6+F6)/(C6-D6) -> 0.89655172 | L6: 0 | M6: =sum(G6:I6) -> 3 | N6: =M6/(C6-D6) -> 0.10344828 | O6: 1 | P6: 0 | Q6: 45986 | R6: 45714
A7: 3 | B7: cRABS | C7: =countif('All Critical Part'!C:C,B7) -> 65 | D7: 26 | E7: 28 | F7: 11 | G7: 5 | H7: 1 | I7: 0 | J7: =E7/(C7-D7) -> 0.71794872 | K7: =(E7+F7)/(C7-D7) -> 1 | L7: 1 | M7: =sum(G7:I7) -> 6 | N7: =M7/(C7-D7) -> 0.15384615 | O7: 3 | P7: 0 | Q7: 46016 | R7: 45742 | S7: =AVERAGE((K5:K13)) -> 0.93722446
A8: 4 | B8: EDM | C8: =countif('All Critical Part'!C:C,B8) -> 18 | D8: 10 | E8: 4 | F8: 7 | G8: 2 | H8: 2 | I8: 0 | J8: =E8/(C8-D8) -> 0.5 | K8: =(E8+F8)/(C8-D8) -> 1.375 | L8: 0 | M8: =sum(G8:I8) -> 4 | N8: =M8/(C8-D8) -> 0.5 | O8: 0 | P8: 0 | Q8: 46016 | R8: 45742
A9: 5 | B9: FD IMA | C9: =countif('All Critical Part'!C:C,B9) -> 76 | D9: 14 | E9: 55 | F9: 5 | G9: 4 | H9: 4 | I9: 0 | J9: =E9/(C9-D9) -> 0.88709677 | K9: =(E9+F9)/(C9-D9) -> 0.96774194 | L9: 0 | M9: =sum(G9:I9) -> 8 | N9: =M9/(C9-D9) -> 0.12903226 | O9: 0 | P9: 0 | Q9: 45986 | R9: 45683 | S9: Persentase stok yang sudah ada dari 9 mesin
A10: 6 | B10: Filling | C10: =countif('All Critical Part'!C:C,B10) -> 43 | D10: 23 | E10: 13 | F10: 6 | G10: 5 | H10: 3 | I10: 0 | J10: =E10/(C10-D10) -> 0.65 | K10: =(E10+F10)/(C10-D10) -> 0.95 | L10: 1 | M10: =sum(G10:I10) -> 8 | N10: =M10/(C10-D10) -> 0.4 | O10: 1 | P10: 3 | Q10: 46016 | R10: 45742
A11: 7 | B11: Mixing | C11: =countif('All Critical Part'!C:C,B11) -> 13 | D11: 5 | E11: 4 | F11: 1 | G11: 1 | H11: 10 | I11: 3 | J11: =E11/(C11-D11) -> 0.5 | K11: =(E11+F11)/(C11-D11) -> 0.625 | L11: 5 | M11: =sum(G11:I11) -> 14 | N11: =M11/(C11-D11) -> 1.75 | O11: 10 | P11: 1 | Q11: 45683 | R11: 45773 | S11: =AVERAGE(J5:J13) -> 0.68136177
A12: 8 | B12: Tunnel | C12: =countif('All Critical Part'!C:C,B12) -> 45 | D12: 21 | E12: 21 | F12: 2 | G12: 6 | H12: 0 | I12: 2 | J12: =E12/(C12-D12) -> 0.875 | K12: =(E12+F12)/(C12-D12) -> 0.95833333 | L12: 0 | M12: =sum(G12:I12) -> 8 | N12: =M12/(C12-D12) -> 0.33333333 | O12: 1 | P12: 0 | Q12: 46016 | R12: 45742
A13: 9 | B13: Washing | C13: =countif('All Critical Part'!C:C,B13) -> 38 | D13: 12 | E13: 15 | F13: 8 | G13: 2 | H13: 1 | I13: 1 | J13: =E13/(C13-D13) -> 0.57692308 | K13: =(E13+F13)/(C13-D13) -> 0.88461538 | L13: 0 | M13: =sum(G13:I13) -> 4 | N13: =M13/(C13-D13) -> 0.15384615 | O13: 1 | P13: 0 | Q13: 45986 | R13: 45714
A14: 10 | B14: General - Chemical | C14: =countif('All Critical Part'!C:C,B14) -> 18 | D14: 0 | E14: 9 | F14: 0 | G14: 5 | H14: 3 | I14: 0 | J14: =E14/(C14-D14) -> 0.5 | K14: =(E14+F14)/(C14-D14) -> 0.5 | L14: 0 | M14: =sum(G14:I14) -> 8 | N14: =M14/(C14-D14) -> 0.44444444 | O14: 0 | P14: 0 | Q14: 46016 | R14: 45683
A15: 11 | B15: General - Pneumatic | C15: =countif('All Critical Part'!C:C,B15) -> 49 | D15: 0 | E15: 22 | F15: 1 | G15: 22 | H15: 3 | I15: 0 | J15: =E15/(C15-D15) -> 0.44897959 | K15: =(E15+F15)/(C15-D15) -> 0.46938776 | L15: 0 | M15: =sum(G15:I15) -> 25 | N15: =M15/(C15-D15) -> 0.51020408 | O15: 0 | P15: 0 | Q15: 46016 | R15: 45683
A16: 12 | B16: General - Electrical | C16: =countif('All Critical Part'!C:C,B16) -> 73 | D16: 0 | E16: 35 | F16: 0 | G16: 30 | H16: 2 | I16: 0 | J16: =E16/(C16-D16) -> 0.47945205 | K16: =(E16+F16)/(C16-D16) -> 0.47945205 | L16: 0 | M16: =sum(G16:I16) -> 32 | N16: =M16/(C16-D16) -> 0.43835616 | O16: 0 | P16: 0 | Q16: 46016 | R16: 45683
A17: 13 | B17: General - Isolasi | C17: =countif('All Critical Part'!C:C,B17) -> 16 | D17: 0 | E17: 8 | F17: 0 | G17: 3 | H17: 0 | I17: 0 | J17: =E17/(C17-D17) -> 0.5 | K17: =(E17+F17)/(C17-D17) -> 0.5 | L17: 0 | M17: =sum(G17:I17) -> 3 | N17: =M17/(C17-D17) -> 0.1875 | O17: 0 | P17: 0 | Q17: 45986 | R17: 46016
A18: 14 | B18: General - Workshop | C18: =countif('All Critical Part'!C:C,B18) -> 23 | D18: 0 | E18: 5 | F18: 0 | G18: 17 | H18: 0 | I18: 0 | J18: =E18/(C18-D18) -> 0.2173913 | K18: =(E18+F18)/(C18-D18) -> 0.2173913 | L18: 0 | M18: =sum(G18:I18) -> 17 | N18: =M18/(C18-D18) -> 0.73913043 | O18: 0 | P18: 0 | Q18: 45986 | R18: 46016
A19: 15 | B19: General - Baut | C19: =countif('All Critical Part'!C:C,B19) -> 11 | D19: 0 | E19: 1 | F19: 0 | G19: 10 | H19: 0 | I19: 0 | J19: =E19/(C19-D19) -> 0.090909091 | K19: =(E19+F19)/(C19-D19) -> 0.090909091 | L19: 0 | M19: =sum(G19:I19) -> 10 | N19: =M19/(C19-D19) -> 0.90909091 | O19: 0 | P19: 0 | Q19: 45986 | R19: 46016
A20: 16 | B20: General - Plumbing | C20: =countif('All Critical Part'!C:C,B20) -> 80 | D20: 0 | E20: 41 | F20: 0 | G20: 34 | H20: 4 | I20: 0 | J20: =E20/(C20-D20) -> 0.5125 | K20: =(E20+F20)/(C20-D20) -> 0.5125 | L20: 0 | M20: =sum(G20:I20) -> 38 | N20: =M20/(C20-D20) -> 0.475 | O20: 0 | P20: 0 | Q20: 46016 | R20: 45683
A21: 17 | B21: CLU | U21: TRUE
A22: 18 | B22: Cartoning | T22: Sudah punya list | U22: TRUE
A23: 19 | B23: Labelling | T23: Sudah punya list | U23: TRUE
A24: 20 | B24: Isolator SKAN | U24: TRUE
A25: 21 | B25: HPLC | T25: Sudah punya list | U25: TRUE
A26: 22 | B26: Building | T26: Sudah punya list | U26: TRUE
A27: 23 | B27: AHU | C27: =countif('All Critical Part'!C:C,B27) -> 26 | T27: Sudah punya list | U27: TRUE
A28: 24 | B28: PWG & SKID | T28: Sudah punya list | U28: TRUE
A29: 25 | B29: WFIG WFI SKID | T29: Sudah punya list | U29: TRUE
A30: 26 | B30: PSG | T30: Sudah punya list | U30: TRUE
A31: 28 | B31: Isolator Klenzaid | U31: FALSE
A32: 29 | B32: MS30 | T32: Sudah punya list | U32: TRUE
B49: Forklift | C49: =countif('All Critical Part'!C:C,B49) -> 0
B50: GMP Washer | C50: =countif('All Critical Part'!C:C,B50) -> 0
B51: Isolator | C51: =countif('All Critical Part'!C:C,B51) -> 0
B52: N2 Gen | C52: =countif('All Critical Part'!C:C,B52) -> 0
B53: Piping | C53: =countif('All Critical Part'!C:C,B53) -> 0
B54: PWG
B55: WFI Gen
B56: WI Incubator
...

Sheet Data PR
A1: Uniq Code | B1: PR Number | C1: Line Number | D1: Item Number | E1: Description | F1: Qty | G1: UoM | H1: Curr | I1: Unit Price | J1: Amount | K1: Need By Date | L1: Ship To | M1: User | N1: User Location | O1: CoA | P1: Line Status | Q1: Order Number | R1: Creation Date | S1: Approval Date | T1: Deadline
A2: =IFERROR(__xludf.DUMMYFUNCTION("FILTER( IMPORTRANGE(""1-dQuO-dirpd7144O3pZq8VkGXSA12p4ZTEYRJJJN7zc"", ""Sheet1!B:U""), (IMPORTRANGE(""1-dQuO-dirpd7144O3pZq8VkGXSA12p4ZTEYRJJJN7zc"", ""Sheet1!Q:Q"") = ""PR Open"") + (IMPORTRANGE(""1-dQuO-dirpd7144O3pZq8VkGXSA12p4ZTEYRJJJN7zc"", ""S"&"heet1!Q:Q"") = ""PO Open"") + (IMPORTRANGE(""1-dQuO-dirpd7144O3pZq8VkGXSA12p4ZTEYRJJJN7zc"", ""Sheet1!Q:Q"") = ""PO Closed"") )"),"181750042-1") -> 181750042-1 | B2: =IFERROR(__xludf.DUMMYFUNCTION("""COMPUTED_VALUE"""),"181750042 - Approved") -> 181750042 - Approved | C2: =IFERROR(__xludf.DUMMYFUNCTION("""COMPUTED_VALUE"""),1.0) -> 1 | D2: =IFERROR(__xludf.DUMMYFUNCTION("""COMPUTED_VALUE"""),"P-15905-00") -> P-15905-00 | E2: =IFERROR(__xludf.DUMMYFUNCTION("""COMPUTED_VALUE"""),"Filter Catridge; Type: TefTEC Series; P/N : TefTEC 0.2 - 10 P7S; Lenght : 10 Inch; O-Ring : 226 Fin; ; ;") -> Filter Catridge; Type: TefTEC Series; P/N : TefTEC 0.2 - 10 P7S; Lenght : 10 Inch; O-Ring : 226 Fin; ; ; | F2: =IFERROR(__xludf.DUMMYFUNCTION("""COMPUTED_VALUE"""),1.0) -> 1 | G2: =IFERROR(__xludf.DUMMYFUNCTION("""COMPUTED_VALUE"""),"Unit") -> Unit | H2: =IFERROR(__xludf.DUMMYFUNCTION("""COMPUTED_VALUE"""),"IDR") -> IDR | I2: =IFERROR(__xludf.DUMMYFUNCTION("""COMPUTED_VALUE"""),3575000.0) -> 3575000 | J2: =IFERROR(__xludf.DUMMYFUNCTION("""COMPUTED_VALUE"""),3575000.0) -> 3575000 | K2: =IFERROR(__xludf.DUMMYFUNCTION("""COMPUTED_VALUE"""),43189.0) -> 43189 | L2: =IFERROR(__xludf.DUMMYFUNCTION("""COMPUTED_VALUE"""),"FIP Engineering") -> FIP Engineering | M2: =IFERROR(__xludf.DUMMYFUNCTION("""COMPUTED_VALUE"""),"Joko Nugroho") -> Joko Nugroho | N2: =IFERROR(__xludf.DUMMYFUNCTION("""COMPUTED_VALUE"""),"FIP Engineering") -> FIP Engineering | O2: =IFERROR(__xludf.DUMMYFUNCTION("""COMPUTED_VALUE"""),"FIP-DOM-000-11304-OS00001-INA-000000") -> FIP-DOM-000-11304-OS00001-INA-000000 | P2: =IFERROR(__xludf.DUMMYFUNCTION("""COMPUTED_VALUE"""),"PO Closed") -> PO Closed | Q2: =IFERROR(__xludf.DUMMYFUNCTION("""COMPUTED_VALUE"""),"GL1802051") -> GL1802051 | R2: =IFERROR(__xludf.DUMMYFUNCTION("""COMPUTED_VALUE"""),43136.0) -> 43136 | S2: =IFERROR(__xludf.DUMMYFUNCTION("""COMPUTED_VALUE"""),"-") -> - | T2: =IFERROR(__xludf.DUMMYFUNCTION("""COMPUTED_VALUE"""),43160.0) -> 43160
A3: =IFERROR(__xludf.DUMMYFUNCTION("""COMPUTED_VALUE"""),"181750042-2") -> 181750042-2 | B3: =IFERROR(__xludf.DUMMYFUNCTION("""COMPUTED_VALUE"""),"181750042 - Approved") -> 181750042 - Approved | C3: =IFERROR(__xludf.DUMMYFUNCTION("""COMPUTED_VALUE"""),2.0) -> 2 | D3: =IFERROR(__xludf.DUMMYFUNCTION("""COMPUTED_VALUE"""),"P-15904-00") -> P-15904-00 | E3: =IFERROR(__xludf.DUMMYFUNCTION("""COMPUTED_VALUE"""),"Filter Catridge; Type : TefTEC Series; P/N : TefTEC 0.2 - 5 P7S; Micron : 0.2 Micron; Lenght : 5 Inc; ; ;") -> Filter Catridge; Type : TefTEC Series; P/N : TefTEC 0.2 - 5 P7S; Micron : 0.2 Micron; Lenght : 5 Inc; ; ; | F3: =IFERROR(__xludf.DUMMYFUNCTION("""COMPUTED_VALUE"""),1.0) -> 1 | G3: =IFERROR(__xludf.DUMMYFUNCTION("""COMPUTED_VALUE"""),"Unit") -> Unit | H3: =IFERROR(__xludf.DUMMYFUNCTION("""COMPUTED_VALUE"""),"IDR") -> IDR | I3: =IFERROR(__xludf.DUMMYFUNCTION("""COMPUTED_VALUE"""),2850000.0) -> 2850000 | J3: =IFERROR(__xludf.DUMMYFUNCTION("""COMPUTED_VALUE"""),2850000.0) -> 2850000 | K3: =IFERROR(__xludf.DUMMYFUNCTION("""COMPUTED_VALUE"""),43189.0) -> 43189 | L3: =IFERROR(__xludf.DUMMYFUNCTION("""COMPUTED_VALUE"""),"FIP Engineering") -> FIP Engineering | M3: =IFERROR(__xludf.DUMMYFUNCTION("""COMPUTED_VALUE"""),"Joko Nugroho") -> Joko Nugroho | N3: =IFERROR(__xludf.DUMMYFUNCTION("""COMPUTED_VALUE"""),"FIP Engineering") -> FIP Engineering | O3: =IFERROR(__xludf.DUMMYFUNCTION("""COMPUTED_VALUE"""),"FIP-DOM-000-11304-OS00001-INA-000000") -> FIP-DOM-000-11304-OS00001-INA-000000 | P3: =IFERROR(__xludf.DUMMYFUNCTION("""COMPUTED_VALUE"""),"PO Closed") -> PO Closed | Q3: =IFERROR(__xludf.DUMMYFUNCTION("""COMPUTED_VALUE"""),"GL1802051") -> GL1802051 | R3: =IFERROR(__xludf.DUMMYFUNCTION("""COMPUTED_VALUE"""),43136.0) -> 43136 | S3: =IFERROR(__xludf.DUMMYFUNCTION("""COMPUTED_VALUE"""),"-") -> - | T3: =IFERROR(__xludf.DUMMYFUNCTION("""COMPUTED_VALUE"""),43160.0) -> 43160
A4: =IFERROR(__xludf.DUMMYFUNCTION("""COMPUTED_VALUE"""),"181750039-5") -> 181750039-5 | B4: =IFERROR(__xludf.DUMMYFUNCTION("""COMPUTED_VALUE"""),"181750039 - Approved") -> 181750039 - Approved | C4: =IFERROR(__xludf.DUMMYFUNCTION("""COMPUTED_VALUE"""),5.0) -> 5 | D4: =IFERROR(__xludf.DUMMYFUNCTION("""COMPUTED_VALUE"""),"P-15446-00") -> P-15446-00 | E4: =IFERROR(__xludf.DUMMYFUNCTION("""COMPUTED_VALUE"""),"Flowmeter Merk Wiebrock; 60 LPM 0-60 liter/menit; ; ;") -> Flowmeter Merk Wiebrock; 60 LPM 0-60 liter/menit; ; ; | F4: =IFERROR(__xludf.DUMMYFUNCTION("""COMPUTED_VALUE"""),2.0) -> 2 | G4: =IFERROR(__xludf.DUMMYFUNCTION("""COMPUTED_VALUE"""),"Unit") -> Unit | H4: =IFERROR(__xludf.DUMMYFUNCTION("""COMPUTED_VALUE"""),"IDR") -> IDR | I4: =IFERROR(__xludf.DUMMYFUNCTION("""COMPUTED_VALUE"""),876000.0) -> 876000 | J4: =IFERROR(__xludf.DUMMYFUNCTION("""COMPUTED_VALUE"""),1752000.0) -> 1752000 | K4: =IFERROR(__xludf.DUMMYFUNCTION("""COMPUTED_VALUE"""),43159.0) -> 43159 | L4: =IFERROR(__xludf.DUMMYFUNCTION("""COMPUTED_VALUE"""),"FIP General") -> FIP General | M4: =IFERROR(__xludf.DUMMYFUNCTION("""COMPUTED_VALUE"""),"Joko Nugroho") -> Joko Nugroho | N4: =IFERROR(__xludf.DUMMYFUNCTION("""COMPUTED_VALUE"""),"FIP Engineering") -> FIP Engineering | O4: =IFERROR(__xludf.DUMMYFUNCTION("""COMPUTED_VALUE"""),"FIP-DOM-ENG-51404-0000000-INA-000000") -> FIP-DOM-ENG-51404-0000000-INA-000000 | P4: =IFERROR(__xludf.DUMMYFUNCTION("""COMPUTED_VALUE"""),"PO Closed") -> PO Closed | Q4: =IFERROR(__xludf.DUMMYFUNCTION("""COMPUTED_VALUE"""),"GL1803032") -> GL1803032 | R4: =IFERROR(__xludf.DUMMYFUNCTION("""COMPUTED_VALUE"""),43139.0) -> 43139 | S4: =IFERROR(__xludf.DUMMYFUNCTION("""COMPUTED_VALUE"""),"-") -> - | T4: =IFERROR(__xludf.DUMMYFUNCTION("""COMPUTED_VALUE"""),43174.0) -> 43174
A5: =IFERROR(__xludf.DUMMYFUNCTION("""COMPUTED_VALUE"""),"181750039-5") -> 181750039-5 | B5: =IFERROR(__xludf.DUMMYFUNCTION("""COMPUTED_VALUE"""),"181750039 - Approved") -> 181750039 - Approved | C5: =IFERROR(__xludf.DUMMYFUNCTION("""COMPUTED_VALUE"""),5.0) -> 5 | D5: =IFERROR(__xludf.DUMMYFUNCTION("""COMPUTED_VALUE"""),"P-15448-00") -> P-15448-00 | E5: =IFERROR(__xludf.DUMMYFUNCTION("""COMPUTED_VALUE"""),"Flowmeter Mfg : Dwyer; Type : MMA-5; ; ;") -> Flowmeter Mfg : Dwyer; Type : MMA-5; ; ; | F5: =IFERROR(__xludf.DUMMYFUNCTION("""COMPUTED_VALUE"""),1.0) -> 1 | G5: =IFERROR(__xludf.DUMMYFUNCTION("""COMPUTED_VALUE"""),"Unit") -> Unit | H5: =IFERROR(__xludf.DUMMYFUNCTION("""COMPUTED_VALUE"""),"IDR") -> IDR | I5: =IFERROR(__xludf.DUMMYFUNCTION("""COMPUTED_VALUE"""),782000.0) -> 782000 | J5: =IFERROR(__xludf.DUMMYFUNCTION("""COMPUTED_VALUE"""),782000.0) -> 782000 | K5: =IFERROR(__xludf.DUMMYFUNCTION("""COMPUTED_VALUE"""),43159.0) -> 43159 | L5: =IFERROR(__xludf.DUMMYFUNCTION("""COMPUTED_VALUE"""),"FIP General") -> FIP General | M5: =IFERROR(__xludf.DUMMYFUNCTION("""COMPUTED_VALUE"""),"Joko Nugroho") -> Joko Nugroho | N5: =IFERROR(__xludf.DUMMYFUNCTION("""COMPUTED_VALUE"""),"FIP Engineering") -> FIP Engineering | O5: =IFERROR(__xludf.DUMMYFUNCTION("""COMPUTED_VALUE"""),"FIP-DOM-ENG-51404-0000000-INA-000000") -> FIP-DOM-ENG-51404-0000000-INA-000000 | P5: =IFERROR(__xludf.DUMMYFUNCTION("""COMPUTED_VALUE"""),"PO Closed") -> PO Closed | Q5: =IFERROR(__xludf.DUMMYFUNCTION("""COMPUTED_VALUE"""),"GL1802043") -> GL1802043 | R5: =IFERROR(__xludf.DUMMYFUNCTION("""COMPUTED_VALUE"""),43139.0) -> 43139 | S5: =IFERROR(__xludf.DUMMYFUNCTION("""COMPUTED_VALUE"""),"-") -> - | T5: =IFERROR(__xludf.DUMMYFUNCTION("""COMPUTED_VALUE"""),43208.0) -> 43208
A6: =IFERROR(__xludf.DUMMYFUNCTION("""COMPUTED_VALUE"""),"181750039-5") -> 181750039-5 | B6: =IFERROR(__xludf.DUMMYFUNCTION("""COMPUTED_VALUE"""),"181750039 - Approved") -> 181750039 - Approved | C6: =IFERROR(__xludf.DUMMYFUNCTION("""COMPUTED_VALUE"""),5.0) -> 5 | D6: =IFERROR(__xludf.DUMMYFUNCTION("""COMPUTED_VALUE"""),"P-15447-00") -> P-15447-00 | E6: =IFERROR(__xludf.DUMMYFUNCTION("""COMPUTED_VALUE"""),"Flowmeter Merk Wiebrock; 100 LPM, 0 - 100liter / menit; ; ;") -> Flowmeter Merk Wiebrock; 100 LPM, 0 - 100liter / menit; ; ; | F6: =IFERROR(__xludf.DUMMYFUNCTION("""COMPUTED_VALUE"""),1.0) -> 1 | G6: =IFERROR(__xludf.DUMMYFUNCTION("""COMPUTED_VALUE"""),"Unit") -> Unit | H6: =IFERROR(__xludf.DUMMYFUNCTION("""COMPUTED_VALUE"""),"IDR") -> IDR | I6: =IFERROR(__xludf.DUMMYFUNCTION("""COMPUTED_VALUE"""),792000.0) -> 792000 | J6: =IFERROR(__xludf.DUMMYFUNCTION("""COMPUTED_VALUE"""),792000.0) -> 792000 | K6: =IFERROR(__xludf.DUMMYFUNCTION("""COMPUTED_VALUE"""),43159.0) -> 43159 | L6: =IFERROR(__xludf.DUMMYFUNCTION("""COMPUTED_VALUE"""),"FIP General") -> FIP General | M6: =IFERROR(__xludf.DUMMYFUNCTION("""COMPUTED_VALUE"""),"Joko Nugroho") -> Joko Nugroho | N6: =IFERROR(__xludf.DUMMYFUNCTION("""COMPUTED_VALUE"""),"FIP Engineering") -> FIP Engineering | O6: =IFERROR(__xludf.DUMMYFUNCTION("""COMPUTED_VALUE"""),"FIP-DOM-ENG-51404-0000000-INA-000000") -> FIP-DOM-ENG-51404-0000000-INA-000000 | P6: =IFERROR(__xludf.DUMMYFUNCTION("""COMPUTED_VALUE"""),"PO Closed") -> PO Closed | Q6: =IFERROR(__xludf.DUMMYFUNCTION("""COMPUTED_VALUE"""),"GL1803052") -> GL1803052 | R6: =IFERROR(__xludf.DUMMYFUNCTION("""COMPUTED_VALUE"""),43139.0) -> 43139 | S6: =IFERROR(__xludf.DUMMYFUNCTION("""COMPUTED_VALUE"""),"-") -> - | T6: =IFERROR(__xludf.DUMMYFUNCTION("""COMPUTED_VALUE"""),43208.0) -> 43208
A7: =IFERROR(__xludf.DUMMYFUNCTION("""COMPUTED_VALUE"""),"181750039-5") -> 181750039-5 | B7: =IFERROR(__xludf.DUMMYFUNCTION("""COMPUTED_VALUE"""),"181750039 - Approved") -> 181750039 - Approved | C7: =IFERROR(__xludf.DUMMYFUNCTION("""COMPUTED_VALUE"""),5.0) -> 5 | D7: =IFERROR(__xludf.DUMMYFUNCTION("""COMPUTED_VALUE"""),"P-15449-00") -> P-15449-00 | E7: =IFERROR(__xludf.DUMMYFUNCTION("""COMPUTED_VALUE"""),"Flowmeter Mfg : Dwyer; Type : RMA-1-SSV-ARB; Range : 0.05-0.4 SCFH AIR; ; ;") -> Flowmeter Mfg : Dwyer; Type : RMA-1-SSV-ARB; Range : 0.05-0.4 SCFH AIR; ; ; | F7: =IFERROR(__xludf.DUMMYFUNCTION("""COMPUTED_VALUE"""),1.0) -> 1 | G7: =IFERROR(__xludf.DUMMYFUNCTION("""COMPUTED_VALUE"""),"Unit") -> Unit | H7: =IFERROR(__xludf.DUMMYFUNCTION("""COMPUTED_VALUE"""),"IDR") -> IDR | I7: =IFERROR(__xludf.DUMMYFUNCTION("""COMPUTED_VALUE"""),1232500.0) -> 1232500 | J7: =IFERROR(__xludf.DUMMYFUNCTION("""COMPUTED_VALUE"""),1232500.0) -> 1232500 | K7: =IFERROR(__xludf.DUMMYFUNCTION("""COMPUTED_VALUE"""),43159.0) -> 43159 | L7: =IFERROR(__xludf.DUMMYFUNCTION("""COMPUTED_VALUE"""),"FIP General") -> FIP General | M7: =IFERROR(__xludf.DUMMYFUNCTION("""COMPUTED_VALUE"""),"Joko Nugroho") -> Joko Nugroho | N7: =IFERROR(__xludf.DUMMYFUNCTION("""COMPUTED_VALUE"""),"FIP Engineering") -> FIP Engineering | O7: =IFERROR(__xludf.DUMMYFUNCTION("""COMPUTED_VALUE"""),"FIP-DOM-ENG-51404-0000000-INA-000000") -> FIP-DOM-ENG-51404-0000000-INA-000000 | P7: =IFERROR(__xludf.DUMMYFUNCTION("""COMPUTED_VALUE"""),"PO Closed") -> PO Closed | Q7: =IFERROR(__xludf.DUMMYFUNCTION("""COMPUTED_VALUE"""),"GL1802043") -> GL1802043 | R7: =IFERROR(__xludf.DUMMYFUNCTION("""COMPUTED_VALUE"""),43139.0) -> 43139 | S7: =IFERROR(__xludf.DUMMYFUNCTION("""COMPUTED_VALUE"""),"-") -> - | T7: =IFERROR(__xludf.DUMMYFUNCTION("""COMPUTED_VALUE"""),43208.0) -> 43208
A8: =IFERROR(__xludf.DUMMYFUNCTION("""COMPUTED_VALUE"""),"181750039-2") -> 181750039-2 | B8: =IFERROR(__xludf.DUMMYFUNCTION("""COMPUTED_VALUE"""),"181750039 - Approved") -> 181750039 - Approved | C8: =IFERROR(__xludf.DUMMYFUNCTION("""COMPUTED_VALUE"""),2.0) -> 2 | D8: =IFERROR(__xludf.DUMMYFUNCTION("""COMPUTED_VALUE"""),"O-15902-00") -> O-15902-00 | E8: =IFERROR(__xludf.DUMMYFUNCTION("""COMPUTED_VALUE"""),"Suction Cup capping size 6R; P/N : 011010; ; ;") -> Suction Cup capping size 6R; P/N : 011010; ; ; | F8: =IFERROR(__xludf.DUMMYFUNCTION("""COMPUTED_VALUE"""),12.0) -> 12 | G8: =IFERROR(__xludf.DUMMYFUNCTION("""COMPUTED_VALUE"""),"Pieces") -> Pieces | H8: =IFERROR(__xludf.DUMMYFUNCTION("""COMPUTED_VALUE"""),"IDR") -> IDR | I8: =IFERROR(__xludf.DUMMYFUNCTION("""COMPUTED_VALUE"""),36000.0) -> 36000 | J8: =IFERROR(__xludf.DUMMYFUNCTION("""COMPUTED_VALUE"""),432000.0) -> 432000 | K8: =IFERROR(__xludf.DUMMYFUNCTION("""COMPUTED_VALUE"""),43157.0) -> 43157 | L8: =IFERROR(__xludf.DUMMYFUNCTION("""COMPUTED_VALUE"""),"FIP Engineering") -> FIP Engineering | M8: =IFERROR(__xludf.DUMMYFUNCTION("""COMPUTED_VALUE"""),"Joko Nugroho") -> Joko Nugroho | N8: =IFERROR(__xludf.DUMMYFUNCTION("""COMPUTED_VALUE"""),"FIP Engineering") -> FIP Engineering | O8: =IFERROR(__xludf.DUMMYFUNCTION("""COMPUTED_VALUE"""),"FIP-DOM-000-11304-OS00001-INA-000000") -> FIP-DOM-000-11304-OS00001-INA-000000 | P8: =IFERROR(__xludf.DUMMYFUNCTION("""COMPUTED_VALUE"""),"PO Closed") -> PO Closed | Q8: =IFERROR(__xludf.DUMMYFUNCTION("""COMPUTED_VALUE"""),"GL1802044") -> GL1802044 | R8: =IFERROR(__xludf.DUMMYFUNCTION("""COMPUTED_VALUE"""),43144.0) -> 43144 | S8: =IFERROR(__xludf.DUMMYFUNCTION("""COMPUTED_VALUE"""),"-") -> - | T8: =IFERROR(__xludf.DUMMYFUNCTION("""COMPUTED_VALUE"""),43227.0) -> 43227
A9: =IFERROR(__xludf.DUMMYFUNCTION("""COMPUTED_VALUE"""),"181750047-3") -> 181750047-3 | B9: =IFERROR(__xludf.DUMMYFUNCTION("""COMPUTED_VALUE"""),"181750047 - Approved") -> 181750047 - Approved | C9: =IFERROR(__xludf.DUMMYFUNCTION("""COMPUTED_VALUE"""),3.0) -> 3 | D9: =IFERROR(__xludf.DUMMYFUNCTION("""COMPUTED_VALUE"""),"O-15902-00") -> O-15902-00 | E9: =IFERROR(__xludf.DUMMYFUNCTION("""COMPUTED_VALUE"""),"Suction Cup capping size 6R; P/N : 011010; ; ;") -> Suction Cup capping size 6R; P/N : 011010; ; ; | F9: =IFERROR(__xludf.DUMMYFUNCTION("""COMPUTED_VALUE"""),28.0) -> 28 | G9: =IFERROR(__xludf.DUMMYFUNCTION("""COMPUTED_VALUE"""),"Pieces") -> Pieces | H9: =IFERROR(__xludf.DUMMYFUNCTION("""COMPUTED_VALUE"""),"IDR") -> IDR | I9: =IFERROR(__xludf.DUMMYFUNCTION("""COMPUTED_VALUE"""),36000.0) -> 36000 | J9: =IFERROR(__xludf.DUMMYFUNCTION("""COMPUTED_VALUE"""),1008000.0) -> 1008000 | K9: =IFERROR(__xludf.DUMMYFUNCTION("""COMPUTED_VALUE"""),43171.0) -> 43171 | L9: =IFERROR(__xludf.DUMMYFUNCTION("""COMPUTED_VALUE"""),"FIP Engineering") -> FIP Engineering | M9: =IFERROR(__xludf.DUMMYFUNCTION("""COMPUTED_VALUE"""),"Joko Nugroho") -> Joko Nugroho | N9: =IFERROR(__xludf.DUMMYFUNCTION("""COMPUTED_VALUE"""),"FIP Engineering") -> FIP Engineering | O9: =IFERROR(__xludf.DUMMYFUNCTION("""COMPUTED_VALUE"""),"FIP-DOM-000-11304-OS00001-INA-000000") -> FIP-DOM-000-11304-OS00001-INA-000000 | P9: =IFERROR(__xludf.DUMMYFUNCTION("""COMPUTED_VALUE"""),"PO Closed") -> PO Closed | Q9: =IFERROR(__xludf.DUMMYFUNCTION("""COMPUTED_VALUE"""),"GL1802044") -> GL1802044 | R9: =IFERROR(__xludf.DUMMYFUNCTION("""COMPUTED_VALUE"""),43144.0) -> 43144 | S9: =IFERROR(__xludf.DUMMYFUNCTION("""COMPUTED_VALUE"""),"-") -> - | T9: =IFERROR(__xludf.DUMMYFUNCTION("""COMPUTED_VALUE"""),43227.0) -> 43227
A10: =IFERROR(__xludf.DUMMYFUNCTION("""COMPUTED_VALUE"""),"181750054-1") -> 181750054-1 | B10: =IFERROR(__xludf.DUMMYFUNCTION("""COMPUTED_VALUE"""),"181750054 - Approved") -> 181750054 - Approved | C10: =IFERROR(__xludf.DUMMYFUNCTION("""COMPUTED_VALUE"""),1.0) -> 1 | D10: =IFERROR(__xludf.DUMMYFUNCTION("""COMPUTED_VALUE"""),"O-14594-00") -> O-14594-00 | E10: =IFERROR(__xludf.DUMMYFUNCTION("""COMPUTED_VALUE"""),"Kit, membrane ozone 6510; ; ;") -> Kit, membrane ozone 6510; ; ; | F10: =IFERROR(__xludf.DUMMYFUNCTION("""COMPUTED_VALUE"""),1.0) -> 1 | G10: =IFERROR(__xludf.DUMMYFUNCTION("""COMPUTED_VALUE"""),"Unit") -> Unit | H10: =IFERROR(__xludf.DUMMYFUNCTION("""COMPUTED_VALUE"""),"IDR") -> IDR | I10: =IFERROR(__xludf.DUMMYFUNCTION("""COMPUTED_VALUE"""),1.032365E7) -> 10323650 | J10: =IFERROR(__xludf.DUMMYFUNCTION("""COMPUTED_VALUE"""),1.032365E7) -> 10323650 | K10: =IFERROR(__xludf.DUMMYFUNCTION("""COMPUTED_VALUE"""),43192.0) -> 43192 | L10: =IFERROR(__xludf.DUMMYFUNCTION("""COMPUTED_VALUE"""),"FIP Engineering") -> FIP Engineering | M10: =IFERROR(__xludf.DUMMYFUNCTION("""COMPUTED_VALUE"""),"Joko Nugroho") -> Joko Nugroho | N10: =IFERROR(__xludf.DUMMYFUNCTION("""COMPUTED_VALUE"""),"FIP Engineering") -> FIP Engineering | O10: =IFERROR(__xludf.DUMMYFUNCTION("""COMPUTED_VALUE"""),"FIP-DOM-000-11304-OS00001-INA-000000") -> FIP-DOM-000-11304-OS00001-INA-000000 | P10: =IFERROR(__xludf.DUMMYFUNCTION("""COMPUTED_VALUE"""),"PO Closed") -> PO Closed | Q10: =IFERROR(__xludf.DUMMYFUNCTION("""COMPUTED_VALUE"""),"GL1802045") -> GL1802045 | R10: =IFERROR(__xludf.DUMMYFUNCTION("""COMPUTED_VALUE"""),43145.0) -> 43145 | S10: =IFERROR(__xludf.DUMMYFUNCTION("""COMPUTED_VALUE"""),"-") -> - | T10: =IFERROR(__xludf.DUMMYFUNCTION("""COMPUTED_VALUE"""),43209.0) -> 43209
A11: =IFERROR(__xludf.DUMMYFUNCTION("""COMPUTED_VALUE"""),"181750047-3") -> 181750047-3 | B11: =IFERROR(__xludf.DUMMYFUNCTION("""COMPUTED_VALUE"""),"181750047 - Approved") -> 181750047 - Approved | C11: =IFERROR(__xludf.DUMMYFUNCTION("""COMPUTED_VALUE"""),3.0) -> 3 | D11: =IFERROR(__xludf.DUMMYFUNCTION("""COMPUTED_VALUE"""),"S-62033-00") -> S-62033-00 | E11: =IFERROR(__xludf.DUMMYFUNCTION("""COMPUTED_VALUE"""),"Regulator Hidrogen Yamato; ; ;") -> Regulator Hidrogen Yamato; ; ; | F11: =IFERROR(__xludf.DUMMYFUNCTION("""COMPUTED_VALUE"""),1.0) -> 1 | G11: =IFERROR(__xludf.DUMMYFUNCTION("""COMPUTED_VALUE"""),"Unit") -> Unit | H11: =IFERROR(__xludf.DUMMYFUNCTION("""COMPUTED_VALUE"""),"IDR") -> IDR | I11: =IFERROR(__xludf.DUMMYFUNCTION("""COMPUTED_VALUE"""),1260000.0) -> 1260000 | J11: =IFERROR(__xludf.DUMMYFUNCTION("""COMPUTED_VALUE"""),1260000.0) -> 1260000 | K11: =IFERROR(__xludf.DUMMYFUNCTION("""COMPUTED_VALUE"""),43159.0) -> 43159 | L11: =IFERROR(__xludf.DUMMYFUNCTION("""COMPUTED_VALUE"""),"FIP General") -> FIP General | M11: =IFERROR(__xludf.DUMMYFUNCTION("""COMPUTED_VALUE"""),"Joko Nugroho") -> Joko Nugroho | N11: =IFERROR(__xludf.DUMMYFUNCTION("""COMPUTED_VALUE"""),"FIP Engineering") -> FIP Engineering | O11: =IFERROR(__xludf.DUMMYFUNCTION("""COMPUTED_VALUE"""),"FIP-DOM-ENG-51504-0000000-INA-000000") -> FIP-DOM-ENG-51504-0000000-INA-000000 | P11: =IFERROR(__xludf.DUMMYFUNCTION("""COMPUTED_VALUE"""),"PO Closed") -> PO Closed | Q11: =IFERROR(__xludf.DUMMYFUNCTION("""COMPUTED_VALUE"""),"GL1806028") -> GL1806028 | R11: =IFERROR(__xludf.DUMMYFUNCTION("""COMPUTED_VALUE"""),43145.0) -> 43145 | S11: =IFERROR(__xludf.DUMMYFUNCTION("""COMPUTED_VALUE"""),"-") -> - | T11: =IFERROR(__xludf.DUMMYFUNCTION("""COMPUTED_VALUE"""),43280.0) -> 43280
A12: =IFERROR(__xludf.DUMMYFUNCTION("""COMPUTED_VALUE"""),"181750057-2") -> 181750057-2 | B12: =IFERROR(__xludf.DUMMYFUNCTION("""COMPUTED_VALUE"""),"181750057 - Approved") -> 181750057 - Approved | C12: =IFERROR(__xludf.DUMMYFUNCTION("""COMPUTED_VALUE"""),2.0) -> 2 | D12: =IFERROR(__xludf.DUMMYFUNCTION("""COMPUTED_VALUE"""),"P-51027-00") -> P-51027-00 | E12: =IFERROR(__xludf.DUMMYFUNCTION("""COMPUTED_VALUE"""),"Isolasi Kabel SCOTCH super 33+ size: 19 mmx20x0.177 mm ( vinyl electric tape ) Black 3M") -> Isolasi Kabel SCOTCH super 33+ size: 19 mmx20x0.177 mm ( vinyl electric tape ) Black 3M | F12: =IFERROR(__xludf.DUMMYFUNCTION("""COMPUTED_VALUE"""),3.0) -> 3 | G12: =IFERROR(__xludf.DUMMYFUNCTION("""COMPUTED_VALUE"""),"Pieces") -> Pieces | H12: =IFERROR(__xludf.DUMMYFUNCTION("""COMPUTED_VALUE"""),"IDR") -> IDR | I12: =IFERROR(__xludf.DUMMYFUNCTION("""COMPUTED_VALUE"""),47700.0) -> 47700 | J12: =IFERROR(__xludf.DUMMYFUNCTION("""COMPUTED_VALUE"""),143100.0) -> 143100 | K12: =IFERROR(__xludf.DUMMYFUNCTION("""COMPUTED_VALUE"""),43171.0) -> 43171 | L12: =IFERROR(__xludf.DUMMYFUNCTION("""COMPUTED_VALUE"""),"FIP Engineering") -> FIP Engineering | M12: =IFERROR(__xludf.DUMMYFUNCTION("""COMPUTED_VALUE"""),"Joko Nugroho") -> Joko Nugroho | N12: =IFERROR(__xludf.DUMMYFUNCTION("""COMPUTED_VALUE"""),"FIP Engineering") -> FIP Engineering | O12: =IFERROR(__xludf.DUMMYFUNCTION("""COMPUTED_VALUE"""),"FIP-DOM-000-11304-OS00001-INA-000000") -> FIP-DOM-000-11304-OS00001-INA-000000 | P12: =IFERROR(__xludf.DUMMYFUNCTION("""COMPUTED_VALUE"""),"PO Closed") -> PO Closed | Q12: =IFERROR(__xludf.DUMMYFUNCTION("""COMPUTED_VALUE"""),"GL1803022") -> GL1803022 | R12: =IFERROR(__xludf.DUMMYFUNCTION("""COMPUTED_VALUE"""),43146.0) -> 43146 | S12: =IFERROR(__xludf.DUMMYFUNCTION("""COMPUTED_VALUE"""),"-") -> - | T12: =IFERROR(__xludf.DUMMYFUNCTION("""COMPUTED_VALUE"""),43171.0) -> 43171
A13: =IFERROR(__xludf.DUMMYFUNCTION("""COMPUTED_VALUE"""),"181750057-3") -> 181750057-3 | B13: =IFERROR(__xludf.DUMMYFUNCTION("""COMPUTED_VALUE"""),"181750057 - Approved") -> 181750057 - Approved | C13: =IFERROR(__xludf.DUMMYFUNCTION("""COMPUTED_VALUE"""),3.0) -> 3 | D13: =IFERROR(__xludf.DUMMYFUNCTION("""COMPUTED_VALUE"""),"P-53214-00") -> P-53214-00 | E13: =IFERROR(__xludf.DUMMYFUNCTION("""COMPUTED_VALUE"""),"Epoxy Adhesive DEXTONE; ; ;") -> Epoxy Adhesive DEXTONE; ; ; | F13: =IFERROR(__xludf.DUMMYFUNCTION("""COMPUTED_VALUE"""),3.0) -> 3 | G13: =IFERROR(__xludf.DUMMYFUNCTION("""COMPUTED_VALUE"""),"Pieces") -> Pieces | H13: =IFERROR(__xludf.DUMMYFUNCTION("""COMPUTED_VALUE"""),"IDR") -> IDR | I13: =IFERROR(__xludf.DUMMYFUNCTION("""COMPUTED_VALUE"""),13500.0) -> 13500 | J13: =IFERROR(__xludf.DUMMYFUNCTION("""COMPUTED_VALUE"""),40500.0) -> 40500 | K13: =IFERROR(__xludf.DUMMYFUNCTION("""COMPUTED_VALUE"""),43171.0) -> 43171 | L13: =IFERROR(__xludf.DUMMYFUNCTION("""COMPUTED_VALUE"""),"FIP Engineering") -> FIP Engineering | M13: =IFERROR(__xludf.DUMMYFUNCTION("""COMPUTED_VALUE"""),"Joko Nugroho") -> Joko Nugroho | N13: =IFERROR(__xludf.DUMMYFUNCTION("""COMPUTED_VALUE"""),"FIP Engineering") -> FIP Engineering | O13: =IFERROR(__xludf.DUMMYFUNCTION("""COMPUTED_VALUE"""),"FIP-DOM-000-11304-OS00001-INA-000000") -> FIP-DOM-000-11304-OS00001-INA-000000 | P13: =IFERROR(__xludf.DUMMYFUNCTION("""COMPUTED_VALUE"""),"PO Closed") -> PO Closed | Q13: =IFERROR(__xludf.DUMMYFUNCTION("""COMPUTED_VALUE"""),"GL1803022") -> GL1803022 | R13: =IFERROR(__xludf.DUMMYFUNCTION("""COMPUTED_VALUE"""),43146.0) -> 43146 | S13: =IFERROR(__xludf.DUMMYFUNCTION("""COMPUTED_VALUE"""),"-") -> - | T13: =IFERROR(__xludf.DUMMYFUNCTION("""COMPUTED_VALUE"""),43171.0) -> 43171
A14: =IFERROR(__xludf.DUMMYFUNCTION("""COMPUTED_VALUE"""),"181750057-4") -> 181750057-4 | B14: =IFERROR(__xludf.DUMMYFUNCTION("""COMPUTED_VALUE"""),"181750057 - Approved") -> 181750057 - Approved | C14: =IFERROR(__xludf.DUMMYFUNCTION("""COMPUTED_VALUE"""),4.0) -> 4 | D14: =IFERROR(__xludf.DUMMYFUNCTION("""COMPUTED_VALUE"""),"P-12764-00") -> P-12764-00 | E14: =IFERROR(__xludf.DUMMYFUNCTION("""COMPUTED_VALUE"""),"Silicone gasket for ferrule dia 1/2inch Taiwan") -> Silicone gasket for ferrule dia 1/2inch Taiwan | F14: =IFERROR(__xludf.DUMMYFUNCTION("""COMPUTED_VALUE"""),6.0) -> 6 | G14: =IFERROR(__xludf.DUMMYFUNCTION("""COMPUTED_VALUE"""),"Pieces") -> Pieces | H14: =IFERROR(__xludf.DUMMYFUNCTION("""COMPUTED_VALUE"""),"IDR") -> IDR | I14: =IFERROR(__xludf.DUMMYFUNCTION("""COMPUTED_VALUE"""),8000.0) -> 8000 | J14: =IFERROR(__xludf.DUMMYFUNCTION("""COMPUTED_VALUE"""),48000.0) -> 48000 | K14: =IFERROR(__xludf.DUMMYFUNCTION("""COMPUTED_VALUE"""),43171.0) -> 43171 | L14: =IFERROR(__xludf.DUMMYFUNCTION("""COMPUTED_VALUE"""),"FIP Engineering") -> FIP Engineering | M14: =IFERROR(__xludf.DUMMYFUNCTION("""COMPUTED_VALUE"""),"Joko Nugroho") -> Joko Nugroho | N14: =IFERROR(__xludf.DUMMYFUNCTION("""COMPUTED_VALUE"""),"FIP Engineering") -> FIP Engineering | O14: =IFERROR(__xludf.DUMMYFUNCTION("""COMPUTED_VALUE"""),"FIP-DOM-000-11304-OS00001-INA-000000") -> FIP-DOM-000-11304-OS00001-INA-000000 | P14: =IFERROR(__xludf.DUMMYFUNCTION("""COMPUTED_VALUE"""),"PO Closed") -> PO Closed | Q14: =IFERROR(__xludf.DUMMYFUNCTION("""COMPUTED_VALUE"""),"GL1803022") -> GL1803022 | R14: =IFERROR(__xludf.DUMMYFUNCTION("""COMPUTED_VALUE"""),43146.0) -> 43146 | S14: =IFERROR(__xludf.DUMMYFUNCTION("""COMPUTED_VALUE"""),"-") -> - | T14: =IFERROR(__xludf.DUMMYFUNCTION("""COMPUTED_VALUE"""),43171.0) -> 43171
