Workbook

Sheet Search
A1: Item Code | B1: Deskripsi | C1: Qty | D1: Lokator | G1: Keyword 1 | H1: Keyword 2 | I1: Keyword 3 | J1: Keyword 4 | K1: Keyword 5
A2: {=ifna(_xlfn.xlookup(B2,'All Item Code'!B:B,'All Item Code'!A:A,),)} -> O-15565-00 | B2: =IFERROR(__xludf.DUMMYFUNCTION("ifna(if(isblank(G3),filter('All Item Code'!B:B,isnumber(search($G$2,'All Item Code'!B:B)),isnumber(search($H$2,'All Item Code'!B:B)),isnumber(search($I$2,'All Item Code'!B:B)),isnumber(search($J$2,'All Item Code'!B:B)),isnumber(search($K$2,'All Item Code'"&"!B:B))),filter('All Item Code'!B:B,isnumber(search($G$3,'All Item Code'!A:A)))),""Tidak Ada"")"),"EPDM MEMBRANE FOR GEMU PNEUMATIC MEMBRANE VALVE 1/2 (DN15); 2-WAY; AISI316L; RA = 0,5MICRON; PNEUMATICALLY OPERATED, NORMALLY CLOSED") -> EPDM MEMBRANE FOR GEMU PNEUMATIC MEMBRANE VALVE 1/2 (DN15); 2-WAY; AISI316L; RA = 0,5MICRON; PNEUMATICALLY OPERATED, NORMALLY CLOSED | C2: {=if(B2="Tidak Ada",,if(isblank(B2),,ifna(sumif('On Hand'!A:A,A2,'On Hand'!D:D)&" "&_xlfn.xlookup(A2,'All Item Code'!A:A,'All Item Code'!D:D,),0)))} -> 0 | D2: =IFERROR(__xludf.DUMMYFUNCTION("if(isblank(B2),,ifna(textjoin(""; "",,filter('On Hand'!E:E,'On Hand'!A:A=A2)),ifna(xlookup(A2,'On Hand'!A:A,'On Hand'!E:E,),)))"),"") | F2: Input Deskripsi | G2: Membrane valve
A3: {=ifna(_xlfn.xlookup(B3,'All Item Code'!B:B,'All Item Code'!A:A,),)} -> O-15585-00 | B3: =IFERROR(__xludf.DUMMYFUNCTION("""COMPUTED_VALUE"""),"EPDM GASKET FOR GEMU PNEUMATIC MEMBRANE VALVE 1/2 (DN15) HEAT NO. 133057;") -> EPDM GASKET FOR GEMU PNEUMATIC MEMBRANE VALVE 1/2 (DN15) HEAT NO. 133057; | C3: {=if(B3="Tidak Ada",,if(isblank(B3),,ifna(sumif('On Hand'!A:A,A3,'On Hand'!D:D)&" "&_xlfn.xlookup(A3,'All Item Code'!A:A,'All Item Code'!D:D,),0)))} -> 0 | D3: =IFERROR(__xludf.DUMMYFUNCTION("if(isblank(B3),,ifna(textjoin(""; "",,filter('On Hand'!E:E,'On Hand'!A:A=A3)),ifna(xlookup(A3,'On Hand'!A:A,'On Hand'!E:E,),)))"),"") | F3: Input Item Code
A4: {=ifna(_xlfn.xlookup(B4,'All Item Code'!B:B,'All Item Code'!A:A,),)} -> O-15652-00 | B4: =IFERROR(__xludf.DUMMYFUNCTION("""COMPUTED_VALUE"""),"PNEUMATIC MEMBRANE VALVE 1/2' (DN15); STERILINE ; PART NO :5189") -> PNEUMATIC MEMBRANE VALVE 1/2' (DN15); STERILINE ; PART NO :5189 | C4: {=if(B4="Tidak Ada",,if(isblank(B4),,ifna(sumif('On Hand'!A:A,A4,'On Hand'!D:D)&" "&_xlfn.xlookup(A4,'All Item Code'!A:A,'All Item Code'!D:D,),0)))} -> 0 | D4: =IFERROR(__xludf.DUMMYFUNCTION("if(isblank(B4),,ifna(textjoin(""; "",,filter('On Hand'!E:E,'On Hand'!A:A=A4)),ifna(xlookup(A4,'On Hand'!A:A,'On Hand'!E:E,),)))"),"")
A5: {=ifna(_xlfn.xlookup(B5,'All Item Code'!B:B,'All Item Code'!A:A,),)} -> O-15653-00 | B5: =IFERROR(__xludf.DUMMYFUNCTION("""COMPUTED_VALUE"""),"PNEUMATICALLY OPERATED, NORMALLY CLOSED FOR GEMU ; PNEUMATIC MEMBRANE VALVE 1/2 (DN15) 2-WAY VALVE BODY; HEAT NO. 128153;") -> PNEUMATICALLY OPERATED, NORMALLY CLOSED FOR GEMU ; PNEUMATIC MEMBRANE VALVE 1/2 (DN15) 2-WAY VALVE BODY; HEAT NO. 128153; | C5: {=if(B5="Tidak Ada",,if(isblank(B5),,ifna(sumif('On Hand'!A:A,A5,'On Hand'!D:D)&" "&_xlfn.xlookup(A5,'All Item Code'!A:A,'All Item Code'!D:D,),0)))} -> 0 | D5: =IFERROR(__xludf.DUMMYFUNCTION("if(isblank(B5),,ifna(textjoin(""; "",,filter('On Hand'!E:E,'On Hand'!A:A=A5)),ifna(xlookup(A5,'On Hand'!A:A,'On Hand'!E:E,),)))"),"")
A6: {=ifna(_xlfn.xlookup(B6,'All Item Code'!B:B,'All Item Code'!A:A,),)} -> O-18388-00 | B6: =IFERROR(__xludf.DUMMYFUNCTION("""COMPUTED_VALUE"""),"Membrane Valve PTFE/EPDM DN15 type 612 GEMU; ; ;") -> Membrane Valve PTFE/EPDM DN15 type 612 GEMU; ; ; | C6: {=if(B6="Tidak Ada",,if(isblank(B6),,ifna(sumif('On Hand'!A:A,A6,'On Hand'!D:D)&" "&_xlfn.xlookup(A6,'All Item Code'!A:A,'All Item Code'!D:D,),0)))} -> 4 pc | D6: =IFERROR(__xludf.DUMMYFUNCTION("if(isblank(B6),,ifna(textjoin(""; "",,filter('On Hand'!E:E,'On Hand'!A:A=A6)),ifna(xlookup(A6,'On Hand'!A:A,'On Hand'!E:E,),)))"),"F-1") -> F-1
A7: {=ifna(_xlfn.xlookup(B7,'All Item Code'!B:B,'All Item Code'!A:A,),)} -> O-21092-00 | B7: =IFERROR(__xludf.DUMMYFUNCTION("""COMPUTED_VALUE"""),"EDM EDM1 - PNEUMATIC MEMBRANE VALVE 1/2' (DN15) 605 15 D 80 40 17 10/N 1536; -; 5189; 1 Pc") -> EDM EDM1 - PNEUMATIC MEMBRANE VALVE 1/2' (DN15) 605 15 D 80 40 17 10/N 1536; -; 5189; 1 Pc | C7: {=if(B7="Tidak Ada",,if(isblank(B7),,ifna(sumif('On Hand'!A:A,A7,'On Hand'!D:D)&" "&_xlfn.xlookup(A7,'All Item Code'!A:A,'All Item Code'!D:D,),0)))} -> 0 | D7: =IFERROR(__xludf.DUMMYFUNCTION("if(isblank(B7),,ifna(textjoin(""; "",,filter('On Hand'!E:E,'On Hand'!A:A=A7)),ifna(xlookup(A7,'On Hand'!A:A,'On Hand'!E:E,),)))"),"")
A8: {=ifna(_xlfn.xlookup(B8,'All Item Code'!B:B,'All Item Code'!A:A,),)} | C8: {=if(B8="Tidak Ada",,if(isblank(B8),,ifna(sumif('On Hand'!A:A,A8,'On Hand'!D:D)&" "&_xlfn.xlookup(A8,'All Item Code'!A:A,'All Item Code'!D:D,),0)))} | D8: =IFERROR(__xludf.DUMMYFUNCTION("if(isblank(B8),,ifna(textjoin(""; "",,filter('On Hand'!E:E,'On Hand'!A:A=A8)),ifna(xlookup(A8,'On Hand'!A:A,'On Hand'!E:E,),)))"),"")
A9: {=ifna(_xlfn.xlookup(B9,'All Item Code'!B:B,'All Item Code'!A:A,),)} | C9: {=if(B9="Tidak Ada",,if(isblank(B9),,ifna(sumif('On Hand'!A:A,A9,'On Hand'!D:D)&" "&_xlfn.xlookup(A9,'All Item Code'!A:A,'All Item Code'!D:D,),0)))} | D9: =IFERROR(__xludf.DUMMYFUNCTION("if(isblank(B9),,ifna(textjoin(""; "",,filter('On Hand'!E:E,'On Hand'!A:A=A9)),ifna(xlookup(A9,'On Hand'!A:A,'On Hand'!E:E,),)))"),"")
A10: {=ifna(_xlfn.xlookup(B10,'All Item Code'!B:B,'All Item Code'!A:A,),)} | C10: {=if(B10="Tidak Ada",,if(isblank(B10),,ifna(sumif('On Hand'!A:A,A10,'On Hand'!D:D)&" "&_xlfn.xlookup(A10,'All Item Code'!A:A,'All Item Code'!D:D,),0)))} | D10: =IFERROR(__xludf.DUMMYFUNCTION("if(isblank(B10),,ifna(textjoin(""; "",,filter('On Hand'!E:E,'On Hand'!A:A=A10)),ifna(xlookup(A10,'On Hand'!A:A,'On Hand'!E:E,),)))"),"")
A11: {=ifna(_xlfn.xlookup(B11,'All Item Code'!B:B,'All Item Code'!A:A,),)} | C11: {=if(B11="Tidak Ada",,if(isblank(B11),,ifna(sumif('On Hand'!A:A,A11,'On Hand'!D:D)&" "&_xlfn.xlookup(A11,'All Item Code'!A:A,'All Item Code'!D:D,),0)))} | D11: =IFERROR(__xludf.DUMMYFUNCTION("if(isblank(B11),,ifna(textjoin(""; "",,filter('On Hand'!E:E,'On Hand'!A:A=A11)),ifna(xlookup(A11,'On Hand'!A:A,'On Hand'!E:E,),)))"),"")
A12: {=ifna(_xlfn.xlookup(B12,'All Item Code'!B:B,'All Item Code'!A:A,),)} | C12: {=if(B12="Tidak Ada",,if(isblank(B12),,ifna(sumif('On Hand'!A:A,A12,'On Hand'!D:D)&" "&_xlfn.xlookup(A12,'All Item Code'!A:A,'All Item Code'!D:D,),0)))} | D12: =IFERROR(__xludf.DUMMYFUNCTION("if(isblank(B12),,ifna(textjoin(""; "",,filter('On Hand'!E:E,'On Hand'!A:A=A12)),ifna(xlookup(A12,'On Hand'!A:A,'On Hand'!E:E,),)))"),"")
A13: {=ifna(_xlfn.xlookup(B13,'All Item Code'!B:B,'All Item Code'!A:A,),)} | C13: {=if(B13="Tidak Ada",,if(isblank(B13),,ifna(sumif('On Hand'!A:A,A13,'On Hand'!D:D)&" "&_xlfn.xlookup(A13,'All Item Code'!A:A,'All Item Code'!D:D,),0)))} | D13: =IFERROR(__xludf.DUMMYFUNCTION("if(isblank(B13),,ifna(textjoin(""; "",,filter('On Hand'!E:E,'On Hand'!A:A=A13)),ifna(xlookup(A13,'On Hand'!A:A,'On Hand'!E:E,),)))"),"")
A14: {=ifna(_xlfn.xlookup(B14,'All Item Code'!B:B,'All Item Code'!A:A,),)} | C14: {=if(B14="Tidak Ada",,if(isblank(B14),,ifna(sumif('On Hand'!A:A,A14,'On Hand'!D:D)&" "&_xlfn.xlookup(A14,'All Item Code'!A:A,'All Item Code'!D:D,),0)))} | D14: =IFERROR(__xludf.DUMMYFUNCTION("if(isblank(B14),,ifna(textjoin(""; "",,filter('On Hand'!E:E,'On Hand'!A:A=A14)),ifna(xlookup(A14,'On Hand'!A:A,'On Hand'!E:E,),)))"),"")
A15: {=ifna(_xlfn.xlookup(B15,'All Item Code'!B:B,'All Item Code'!A:A,),)} | C15: {=if(B15="Tidak Ada",,if(isblank(B15),,ifna(sumif('On Hand'!A:A,A15,'On Hand'!D:D)&" "&_xlfn.xlookup(A15,'All Item Code'!A:A,'All Item Code'!D:D,),0)))} | D15: =IFERROR(__xludf.DUMMYFUNCTION("if(isblank(B15),,ifna(textjoin(""; "",,filter('On Hand'!E:E,'On Hand'!A:A=A15)),ifna(xlookup(A15,'On Hand'!A:A,'On Hand'!E:E,),)))"),"")
A16: {=ifna(_xlfn.xlookup(B16,'All Item Code'!B:B,'All Item Code'!A:A,),)} | C16: {=if(B16="Tidak Ada",,if(isblank(B16),,ifna(sumif('On Hand'!A:A,A16,'On Hand'!D:D)&" "&_xlfn.xlookup(A16,'All Item Code'!A:A,'All Item Code'!D:D,),0)))} | D16: =IFERROR(__xludf.DUMMYFUNCTION("if(isblank(B16),,ifna(textjoin(""; "",,filter('On Hand'!E:E,'On Hand'!A:A=A16)),ifna(xlookup(A16,'On Hand'!A:A,'On Hand'!E:E,),)))"),"")
A17: {=ifna(_xlfn.xlookup(B17,'All Item Code'!B:B,'All Item Code'!A:A,),)} | C17: {=if(B17="Tidak Ada",,if(isblank(B17),,ifna(sumif('On Hand'!A:A,A17,'On Hand'!D:D)&" "&_xlfn.xlookup(A17,'All Item Code'!A:A,'All Item Code'!D:D,),0)))} | D17: =IFERROR(__xludf.DUMMYFUNCTION("if(isblank(B17),,ifna(textjoin(""; "",,filter('On Hand'!E:E,'On Hand'!A:A=A17)),ifna(xlookup(A17,'On Hand'!A:A,'On Hand'!E:E,),)))"),"")
A18: {=ifna(_xlfn.xlookup(B18,'All Item Code'!B:B,'All Item Code'!A:A,),)} | C18: {=if(B18="Tidak Ada",,if(isblank(B18),,ifna(sumif('On Hand'!A:A,A18,'On Hand'!D:D)&" "&_xlfn.xlookup(A18,'All Item Code'!A:A,'All Item Code'!D:D,),0)))} | D18: =IFERROR(__xludf.DUMMYFUNCTION("if(isblank(B18),,ifna(textjoin(""; "",,filter('On Hand'!E:E,'On Hand'!A:A=A18)),ifna(xlookup(A18,'On Hand'!A:A,'On Hand'!E:E,),)))"),"")
A19: {=ifna(_xlfn.xlookup(B19,'All Item Code'!B:B,'All Item Code'!A:A,),)} | C19: {=if(B19="Tidak Ada",,if(isblank(B19),,ifna(sumif('On Hand'!A:A,A19,'On Hand'!D:D)&" "&_xlfn.xlookup(A19,'All Item Code'!A:A,'All Item Code'!D:D,),0)))} | D19: =IFERROR(__xludf.DUMMYFUNCTION("if(isblank(B19),,ifna(textjoin(""; "",,filter('On Hand'!E:E,'On Hand'!A:A=A19)),ifna(xlookup(A19,'On Hand'!A:A,'On Hand'!E:E,),)))"),"")
A20: {=ifna(_xlfn.xlookup(B20,'All Item Code'!B:B,'All Item Code'!A:A,),)} | C20: {=if(B20="Tidak Ada",,if(isblank(B20),,ifna(sumif('On Hand'!A:A,A20,'On Hand'!D:D)&" "&_xlfn.xlookup(A20,'All Item Code'!A:A,'All Item Code'!D:D,),0)))} | D20: =IFERROR(__xludf.DUMMYFUNCTION("if(isblank(B20),,ifna(textjoin(""; "",,filter('On Hand'!E:E,'On Hand'!A:A=A20)),ifna(xlookup(A20,'On Hand'!A:A,'On Hand'!E:E,),)))"),"")
A21: {=ifna(_xlfn.xlookup(B21,'All Item Code'!B:B,'All Item Code'!A:A,),)} | C21: {=if(B21="Tidak Ada",,if(isblank(B21),,ifna(sumif('On Hand'!A:A,A21,'On Hand'!D:D)&" "&_xlfn.xlookup(A21,'All Item Code'!A:A,'All Item Code'!D:D,),0)))} | D21: =IFERROR(__xludf.DUMMYFUNCTION("if(isblank(B21),,ifna(textjoin(""; "",,filter('On Hand'!E:E,'On Hand'!A:A=A21)),ifna(xlookup(A21,'On Hand'!A:A,'On Hand'!E:E,),)))"),"")
A22: {=ifna(_xlfn.xlookup(B22,'All Item Code'!B:B,'All Item Code'!A:A,),)} | C22: {=if(B22="Tidak Ada",,if(isblank(B22),,ifna(sumif('On Hand'!A:A,A22,'On Hand'!D:D)&" "&_xlfn.xlookup(A22,'All Item Code'!A:A,'All Item Code'!D:D,),0)))} | D22: =IFERROR(__xludf.DUMMYFUNCTION("if(isblank(B22),,ifna(textjoin(""; "",,filter('On Hand'!E:E,'On Hand'!A:A=A22)),ifna(xlookup(A22,'On Hand'!A:A,'On Hand'!E:E,),)))"),"")
A23: {=ifna(_xlfn.xlookup(B23,'All Item Code'!B:B,'All Item Code'!A:A,),)} | C23: {=if(B23="Tidak Ada",,if(isblank(B23),,ifna(sumif('On Hand'!A:A,A23,'On Hand'!D:D)&" "&_xlfn.xlookup(A23,'All Item Code'!A:A,'All Item Code'!D:D,),0)))} | D23: =IFERROR(__xludf.DUMMYFUNCTION("if(isblank(B23),,ifna(textjoin(""; "",,filter('On Hand'!E:E,'On Hand'!A:A=A23)),ifna(xlookup(A23,'On Hand'!A:A,'On Hand'!E:E,),)))"),"")
A24: {=ifna(_xlfn.xlookup(B24,'All Item Code'!B:B,'All Item Code'!A:A,),)} | C24: {=if(B24="Tidak Ada",,if(isblank(B24),,ifna(sumif('On Hand'!A:A,A24,'On Hand'!D:D)&" "&_xlfn.xlookup(A24,'All Item Code'!A:A,'All Item Code'!D:D,),0)))} | D24: =IFERROR(__xludf.DUMMYFUNCTION("if(isblank(B24),,ifna(textjoin(""; "",,filter('On Hand'!E:E,'On Hand'!A:A=A24)),ifna(xlookup(A24,'On Hand'!A:A,'On Hand'!E:E,),)))"),"")
A25: {=ifna(_xlfn.xlookup(B25,'All Item Code'!B:B,'All Item Code'!A:A,),)} | C25: {=if(B25="Tidak Ada",,if(isblank(B25),,ifna(sumif('On Hand'!A:A,A25,'On Hand'!D:D)&" "&_xlfn.xlookup(A25,'All Item Code'!A:A,'All Item Code'!D:D,),0)))} | D25: =IFERROR(__xludf.DUMMYFUNCTION("if(isblank(B25),,ifna(textjoin(""; "",,filter('On Hand'!E:E,'On Hand'!A:A=A25)),ifna(xlookup(A25,'On Hand'!A:A,'On Hand'!E:E,),)))"),"")
A26: {=ifna(_xlfn.xlookup(B26,'All Item Code'!B:B,'All Item Code'!A:A,),)} | C26: {=if(B26="Tidak Ada",,if(isblank(B26),,ifna(sumif('On Hand'!A:A,A26,'On Hand'!D:D)&" "&_xlfn.xlookup(A26,'All Item Code'!A:A,'All Item Code'!D:D,),0)))} | D26: =IFERROR(__xludf.DUMMYFUNCTION("if(isblank(B26),,ifna(textjoin(""; "",,filter('On Hand'!E:E,'On Hand'!A:A=A26)),ifna(xlookup(A26,'On Hand'!A:A,'On Hand'!E:E,),)))"),"")
A27: {=ifna(_xlfn.xlookup(B27,'All Item Code'!B:B,'All Item Code'!A:A,),)} | C27: {=if(B27="Tidak Ada",,if(isblank(B27),,ifna(sumif('On Hand'!A:A,A27,'On Hand'!D:D)&" "&_xlfn.xlookup(A27,'All Item Code'!A:A,'All Item Code'!D:D,),0)))} | D27: =IFERROR(__xludf.DUMMYFUNCTION("if(isblank(B27),,ifna(textjoin(""; "",,filter('On Hand'!E:E,'On Hand'!A:A=A27)),ifna(xlookup(A27,'On Hand'!A:A,'On Hand'!E:E,),)))"),"")
A28: {=ifna(_xlfn.xlookup(B28,'All Item Code'!B:B,'All Item Code'!A:A,),)} | C28: {=if(B28="Tidak Ada",,if(isblank(B28),,ifna(sumif('On Hand'!A:A,A28,'On Hand'!D:D)&" "&_xlfn.xlookup(A28,'All Item Code'!A:A,'All Item Code'!D:D,),0)))} | D28: =IFERROR(__xludf.DUMMYFUNCTION("if(isblank(B28),,ifna(textjoin(""; "",,filter('On Hand'!E:E,'On Hand'!A:A=A28)),ifna(xlookup(A28,'On Hand'!A:A,'On Hand'!E:E,),)))"),"")
A29: {=ifna(_xlfn.xlookup(B29,'All Item Code'!B:B,'All Item Code'!A:A,),)} | C29: {=if(B29="Tidak Ada",,if(isblank(B29),,ifna(sumif('On Hand'!A:A,A29,'On Hand'!D:D)&" "&_xlfn.xlookup(A29,'All Item Code'!A:A,'All Item Code'!D:D,),0)))} | D29: =IFERROR(__xludf.DUMMYFUNCTION("if(isblank(B29),,ifna(textjoin(""; "",,filter('On Hand'!E:E,'On Hand'!A:A=A29)),ifna(xlookup(A29,'On Hand'!A:A,'On Hand'!E:E,),)))"),"")
A30: {=ifna(_xlfn.xlookup(B30,'All Item Code'!B:B,'All Item Code'!A:A,),)} | C30: {=if(B30="Tidak Ada",,if(isblank(B30),,ifna(sumif('On Hand'!A:A,A30,'On Hand'!D:D)&" "&_xlfn.xlookup(A30,'All Item Code'!A:A,'All Item Code'!D:D,),0)))} | D30: =IFERROR(__xludf.DUMMYFUNCTION("if(isblank(B30),,ifna(textjoin(""; "",,filter('On Hand'!E:E,'On Hand'!A:A=A30)),ifna(xlookup(A30,'On Hand'!A:A,'On Hand'!E:E,),)))"),"")
A31: {=ifna(_xlfn.xlookup(B31,'All Item Code'!B:B,'All Item Code'!A:A,),)} | C31: {=if(B31="Tidak Ada",,if(isblank(B31),,ifna(sumif('On Hand'!A:A,A31,'On Hand'!D:D)&" "&_xlfn.xlookup(A31,'All Item Code'!A:A,'All Item Code'!D:D,),0)))} | D31: =IFERROR(__xludf.DUMMYFUNCTION("if(isblank(B31),,ifna(textjoin(""; "",,filter('On Hand'!E:E,'On Hand'!A:A=A31)),ifna(xlookup(A31,'On Hand'!A:A,'On Hand'!E:E,),)))"),"")
A32: {=ifna(_xlfn.xlookup(B32,'All Item Code'!B:B,'All Item Code'!A:A,),)} | C32: {=if(B32="Tidak Ada",,if(isblank(B32),,ifna(sumif('On Hand'!A:A,A32,'On Hand'!D:D)&" "&_xlfn.xlookup(A32,'All Item Code'!A:A,'All Item Code'!D:D,),0)))} | D32: =IFERROR(__xludf.DUMMYFUNCTION("if(isblank(B32),,ifna(textjoin(""; "",,filter('On Hand'!E:E,'On Hand'!A:A=A32)),ifna(xlookup(A32,'On Hand'!A:A,'On Hand'!E:E,),)))"),"")
A33: {=ifna(_xlfn.xlookup(B33,'All Item Code'!B:B,'All Item Code'!A:A,),)} | C33: {=if(B33="Tidak Ada",,if(isblank(B33),,ifna(sumif('On Hand'!A:A,A33,'On Hand'!D:D)&" "&_xlfn.xlookup(A33,'All Item Code'!A:A,'All Item Code'!D:D,),0)))} | D33: =IFERROR(__xludf.DUMMYFUNCTION("if(isblank(B33),,ifna(textjoin(""; "",,filter('On Hand'!E:E,'On Hand'!A:A=A33)),ifna(xlookup(A33,'On Hand'!A:A,'On Hand'!E:E,),)))"),"")
A34: {=ifna(_xlfn.xlookup(B34,'All Item Code'!B:B,'All Item Code'!A:A,),)} | C34: {=if(B34="Tidak Ada",,if(isblank(B34),,ifna(sumif('On Hand'!A:A,A34,'On Hand'!D:D)&" "&_xlfn.xlookup(A34,'All Item Code'!A:A,'All Item Code'!D:D,),0)))} | D34: =IFERROR(__xludf.DUMMYFUNCTION("if(isblank(B34),,ifna(textjoin(""; "",,filter('On Hand'!E:E,'On Hand'!A:A=A34)),ifna(xlookup(A34,'On Hand'!A:A,'On Hand'!E:E,),)))"),"")
A35: {=ifna(_xlfn.xlookup(B35,'All Item Code'!B:B,'All Item Code'!A:A,),)} | C35: {=if(B35="Tidak Ada",,if(isblank(B35),,ifna(sumif('On Hand'!A:A,A35,'On Hand'!D:D)&" "&_xlfn.xlookup(A35,'All Item Code'!A:A,'All Item Code'!D:D,),0)))} | D35: =IFERROR(__xludf.DUMMYFUNCTION("if(isblank(B35),,ifna(textjoin(""; "",,filter('On Hand'!E:E,'On Hand'!A:A=A35)),ifna(xlookup(A35,'On Hand'!A:A,'On Hand'!E:E,),)))"),"")
A36: {=ifna(_xlfn.xlookup(B36,'All Item Code'!B:B,'All Item Code'!A:A,),)} | C36: {=if(B36="Tidak Ada",,if(isblank(B36),,ifna(sumif('On Hand'!A:A,A36,'On Hand'!D:D)&" "&_xlfn.xlookup(A36,'All Item Code'!A:A,'All Item Code'!D:D,),0)))} | D36: =IFERROR(__xludf.DUMMYFUNCTION("if(isblank(B36),,ifna(textjoin(""; "",,filter('On Hand'!E:E,'On Hand'!A:A=A36)),ifna(xlookup(A36,'On Hand'!A:A,'On Hand'!E:E,),)))"),"")
A37: {=ifna(_xlfn.xlookup(B37,'All Item Code'!B:B,'All Item Code'!A:A,),)} | C37: {=if(B37="Tidak Ada",,if(isblank(B37),,ifna(sumif('On Hand'!A:A,A37,'On Hand'!D:D)&" "&_xlfn.xlookup(A37,'All Item Code'!A:A,'All Item Code'!D:D,),0)))} | D37: =IFERROR(__xludf.DUMMYFUNCTION("if(isblank(B37),,ifna(textjoin(""; "",,filter('On Hand'!E:E,'On Hand'!A:A=A37)),ifna(xlookup(A37,'On Hand'!A:A,'On Hand'!E:E,),)))"),"")
A38: {=ifna(_xlfn.xlookup(B38,'All Item Code'!B:B,'All Item Code'!A:A,),)} | C38: {=if(B38="Tidak Ada",,if(isblank(B38),,ifna(sumif('On Hand'!A:A,A38,'On Hand'!D:D)&" "&_xlfn.xlookup(A38,'All Item Code'!A:A,'All Item Code'!D:D,),0)))} | D38: =IFERROR(__xludf.DUMMYFUNCTION("if(isblank(B38),,ifna(textjoin(""; "",,filter('On Hand'!E:E,'On Hand'!A:A=A38)),ifna(xlookup(A38,'On Hand'!A:A,'On Hand'!E:E,),)))"),"")
A39: {=ifna(_xlfn.xlookup(B39,'All Item Code'!B:B,'All Item Code'!A:A,),)} | C39: {=if(B39="Tidak Ada",,if(isblank(B39),,ifna(sumif('On Hand'!A:A,A39,'On Hand'!D:D)&" "&_xlfn.xlookup(A39,'All Item Code'!A:A,'All Item Code'!D:D,),0)))} | D39: =IFERROR(__xludf.DUMMYFUNCTION("if(isblank(B39),,ifna(textjoin(""; "",,filter('On Hand'!E:E,'On Hand'!A:A=A39)),ifna(xlookup(A39,'On Hand'!A:A,'On Hand'!E:E,),)))"),"")
A40: {=ifna(_xlfn.xlookup(B40,'All Item Code'!B:B,'All Item Code'!A:A,),)} | C40: {=if(B40="Tidak Ada",,if(isblank(B40),,ifna(sumif('On Hand'!A:A,A40,'On Hand'!D:D)&" "&_xlfn.xlookup(A40,'All Item Code'!A:A,'All Item Code'!D:D,),0)))} | D40: =IFERROR(__xludf.DUMMYFUNCTION("if(isblank(B40),,ifna(textjoin(""; "",,filter('On Hand'!E:E,'On Hand'!A:A=A40)),ifna(xlookup(A40,'On Hand'!A:A,'On Hand'!E:E,),)))"),"")
...

Sheet All Item Code
A1: =IFERROR(__xludf.DUMMYFUNCTION("importrange(""1ZTUXhF0dnt45v0vHwLa1Fr56SKO64eHyOYXGurqHipk"",""Sheet1!A2:C"")"),"J-10205-02") -> J-10205-02 | B1: =IFERROR(__xludf.DUMMYFUNCTION("""COMPUTED_VALUE"""),"Chlorine Test; Merck; c/n 1.14978.0001; 600 tests/pack") -> Chlorine Test; Merck; c/n 1.14978.0001; 600 tests/pack | C1: =IFERROR(__xludf.DUMMYFUNCTION("""COMPUTED_VALUE"""),"J-10205-02") -> J-10205-02 | D1: =if(isna(vlookup(C1,'On Hand'!A:C,3,0)),"",vlookup(C1,'On Hand'!A:C,3,0))
A2: =IFERROR(__xludf.DUMMYFUNCTION("""COMPUTED_VALUE"""),"O-11109-00") -> O-11109-00 | B2: =IFERROR(__xludf.DUMMYFUNCTION("""COMPUTED_VALUE"""),"Bearing 6002-2RSH") -> Bearing 6002-2RSH | C2: =IFERROR(__xludf.DUMMYFUNCTION("""COMPUTED_VALUE"""),"O-11109-00") -> O-11109-00 | D2: =if(isna(vlookup(C2,'On Hand'!A:C,3,0)),"",vlookup(C2,'On Hand'!A:C,3,0)) -> pc
A3: =IFERROR(__xludf.DUMMYFUNCTION("""COMPUTED_VALUE"""),"O-11145-00") -> O-11145-00 | B3: =IFERROR(__xludf.DUMMYFUNCTION("""COMPUTED_VALUE"""),"Bearing 6201 2Z") -> Bearing 6201 2Z | C3: =IFERROR(__xludf.DUMMYFUNCTION("""COMPUTED_VALUE"""),"O-11145-00") -> O-11145-00 | D3: =if(isna(vlookup(C3,'On Hand'!A:C,3,0)),"",vlookup(C3,'On Hand'!A:C,3,0)) -> pc
A4: =IFERROR(__xludf.DUMMYFUNCTION("""COMPUTED_VALUE"""),"O-11149-00") -> O-11149-00 | B4: =IFERROR(__xludf.DUMMYFUNCTION("""COMPUTED_VALUE"""),"Bearing 6202 ZZ - P/N : - pc") -> Bearing 6202 ZZ - P/N : - pc | C4: =IFERROR(__xludf.DUMMYFUNCTION("""COMPUTED_VALUE"""),"O-11149-00") -> O-11149-00 | D4: =if(isna(vlookup(C4,'On Hand'!A:C,3,0)),"",vlookup(C4,'On Hand'!A:C,3,0)) -> pc
A5: =IFERROR(__xludf.DUMMYFUNCTION("""COMPUTED_VALUE"""),"O-11154-00") -> O-11154-00 | B5: =IFERROR(__xludf.DUMMYFUNCTION("""COMPUTED_VALUE"""),"Bearing 6204 2Z SKF") -> Bearing 6204 2Z SKF | C5: =IFERROR(__xludf.DUMMYFUNCTION("""COMPUTED_VALUE"""),"O-11154-00") -> O-11154-00 | D5: =if(isna(vlookup(C5,'On Hand'!A:C,3,0)),"",vlookup(C5,'On Hand'!A:C,3,0)) -> pc
A6: =IFERROR(__xludf.DUMMYFUNCTION("""COMPUTED_VALUE"""),"O-11162-00") -> O-11162-00 | B6: =IFERROR(__xludf.DUMMYFUNCTION("""COMPUTED_VALUE"""),"Bearing 6205 ZZ") -> Bearing 6205 ZZ | C6: =IFERROR(__xludf.DUMMYFUNCTION("""COMPUTED_VALUE"""),"O-11162-00") -> O-11162-00 | D6: =if(isna(vlookup(C6,'On Hand'!A:C,3,0)),"",vlookup(C6,'On Hand'!A:C,3,0)) -> pc
A7: =IFERROR(__xludf.DUMMYFUNCTION("""COMPUTED_VALUE"""),"O-11166-00") -> O-11166-00 | B7: =IFERROR(__xludf.DUMMYFUNCTION("""COMPUTED_VALUE"""),"Bearing 6206 ZZ") -> Bearing 6206 ZZ | C7: =IFERROR(__xludf.DUMMYFUNCTION("""COMPUTED_VALUE"""),"O-11166-00") -> O-11166-00 | D7: =if(isna(vlookup(C7,'On Hand'!A:C,3,0)),"",vlookup(C7,'On Hand'!A:C,3,0)) -> pc
A8: =IFERROR(__xludf.DUMMYFUNCTION("""COMPUTED_VALUE"""),"O-11169-00") -> O-11169-00 | B8: =IFERROR(__xludf.DUMMYFUNCTION("""COMPUTED_VALUE"""),"Bearing 6207ZZ") -> Bearing 6207ZZ | C8: =IFERROR(__xludf.DUMMYFUNCTION("""COMPUTED_VALUE"""),"O-11169-00") -> O-11169-00 | D8: =if(isna(vlookup(C8,'On Hand'!A:C,3,0)),"",vlookup(C8,'On Hand'!A:C,3,0)) -> pc
A9: =IFERROR(__xludf.DUMMYFUNCTION("""COMPUTED_VALUE"""),"O-11173-00") -> O-11173-00 | B9: =IFERROR(__xludf.DUMMYFUNCTION("""COMPUTED_VALUE"""),"Bearing 6208 SKF") -> Bearing 6208 SKF | C9: =IFERROR(__xludf.DUMMYFUNCTION("""COMPUTED_VALUE"""),"O-11173-00") -> O-11173-00 | D9: =if(isna(vlookup(C9,'On Hand'!A:C,3,0)),"",vlookup(C9,'On Hand'!A:C,3,0)) -> pc
A10: =IFERROR(__xludf.DUMMYFUNCTION("""COMPUTED_VALUE"""),"O-11181-00") -> O-11181-00 | B10: =IFERROR(__xludf.DUMMYFUNCTION("""COMPUTED_VALUE"""),"Bearing 626-2Z") -> Bearing 626-2Z | C10: =IFERROR(__xludf.DUMMYFUNCTION("""COMPUTED_VALUE"""),"O-11181-00") -> O-11181-00 | D10: =if(isna(vlookup(C10,'On Hand'!A:C,3,0)),"",vlookup(C10,'On Hand'!A:C,3,0)) -> pc
A11: =IFERROR(__xludf.DUMMYFUNCTION("""COMPUTED_VALUE"""),"O-11287-00") -> O-11287-00 | B11: =IFERROR(__xludf.DUMMYFUNCTION("""COMPUTED_VALUE"""),"IMA F200 Filling Machine - Pall Mini Kleenpak Capsules with Supor EKV Membrane, Filter Capsule 4,1""/0,2 um/0,02 m2/Hydrophilic PVDF/code2/0,25-0,5"" hose barb; Pall; KA02DFLP8G; 1 pcs") -> IMA F200 Filling Machine - Pall Mini Kleenpak Capsules with Supor EKV Membrane, Filter Capsule 4,1"/0,2 um/0,02 m2/Hydrophilic PVDF/code2/0,25-0,5" hose barb; Pall; KA02DFLP8G; 1 pcs | C11: =IFERROR(__xludf.DUMMYFUNCTION("""COMPUTED_VALUE"""),"O-11287-00") -> O-11287-00 | D11: =if(isna(vlookup(C11,'On Hand'!A:C,3,0)),"",vlookup(C11,'On Hand'!A:C,3,0))
A12: =IFERROR(__xludf.DUMMYFUNCTION("""COMPUTED_VALUE"""),"O-11356-00") -> O-11356-00 | B12: =IFERROR(__xludf.DUMMYFUNCTION("""COMPUTED_VALUE"""),"Lubricant ? Food grade oil Viscolab 150 - Pc=Liter") -> Lubricant ? Food grade oil Viscolab 150 - Pc=Liter | C12: =IFERROR(__xludf.DUMMYFUNCTION("""COMPUTED_VALUE"""),"O-11356-00") -> O-11356-00 | D12: =if(isna(vlookup(C12,'On Hand'!A:C,3,0)),"",vlookup(C12,'On Hand'!A:C,3,0))
A13: =IFERROR(__xludf.DUMMYFUNCTION("""COMPUTED_VALUE"""),"O-11367-00") -> O-11367-00 | B13: =IFERROR(__xludf.DUMMYFUNCTION("""COMPUTED_VALUE"""),"Lubricant ? Oli ISO VG 320 MULTIPRIMA INDOSEJAHTERA, PT P/N : - pc") -> Lubricant ? Oli ISO VG 320 MULTIPRIMA INDOSEJAHTERA, PT P/N : - pc | C13: =IFERROR(__xludf.DUMMYFUNCTION("""COMPUTED_VALUE"""),"O-11367-00") -> O-11367-00 | D13: =if(isna(vlookup(C13,'On Hand'!A:C,3,0)),"",vlookup(C13,'On Hand'!A:C,3,0)) -> L
A14: =IFERROR(__xludf.DUMMYFUNCTION("""COMPUTED_VALUE"""),"O-11761-00") -> O-11761-00 | B14: =IFERROR(__xludf.DUMMYFUNCTION("""COMPUTED_VALUE"""),"Marchesini MA255 Cartoning Machine - Conveyor Belt, PU White, 1380 x 40 x 1.6 mm; Custom/Lokal; -; 1 unt") -> Marchesini MA255 Cartoning Machine - Conveyor Belt, PU White, 1380 x 40 x 1.6 mm; Custom/Lokal; -; 1 unt | C14: =IFERROR(__xludf.DUMMYFUNCTION("""COMPUTED_VALUE"""),"O-11761-00") -> O-11761-00 | D14: =if(isna(vlookup(C14,'On Hand'!A:C,3,0)),"",vlookup(C14,'On Hand'!A:C,3,0)) -> pc
A15: =IFERROR(__xludf.DUMMYFUNCTION("""COMPUTED_VALUE"""),"O-11762-00") -> O-11762-00 | B15: =IFERROR(__xludf.DUMMYFUNCTION("""COMPUTED_VALUE"""),"MARCHESINI MA 255 - Conveyor belt Nastro transporto FNB-8E 1850 X 40 HA; Marchesini; C720718540 pc") -> MARCHESINI MA 255 - Conveyor belt Nastro transporto FNB-8E 1850 X 40 HA; Marchesini; C720718540 pc | C15: =IFERROR(__xludf.DUMMYFUNCTION("""COMPUTED_VALUE"""),"O-11762-00") -> O-11762-00 | D15: =if(isna(vlookup(C15,'On Hand'!A:C,3,0)),"",vlookup(C15,'On Hand'!A:C,3,0)) -> pc
A16: =IFERROR(__xludf.DUMMYFUNCTION("""COMPUTED_VALUE"""),"O-11763-00") -> O-11763-00 | B16: =IFERROR(__xludf.DUMMYFUNCTION("""COMPUTED_VALUE"""),"MARCHESINI MA 255 - Conveyor belt Nastro transporto FNI-5E er 1110x 75(sil); Marchesini; C721411175 pc") -> MARCHESINI MA 255 - Conveyor belt Nastro transporto FNI-5E er 1110x 75(sil); Marchesini; C721411175 pc | C16: =IFERROR(__xludf.DUMMYFUNCTION("""COMPUTED_VALUE"""),"O-11763-00") -> O-11763-00 | D16: =if(isna(vlookup(C16,'On Hand'!A:C,3,0)),"",vlookup(C16,'On Hand'!A:C,3,0)) -> pc
A17: =IFERROR(__xludf.DUMMYFUNCTION("""COMPUTED_VALUE"""),"O-12732-00") -> O-12732-00 | B17: =IFERROR(__xludf.DUMMYFUNCTION("""COMPUTED_VALUE"""),"Tubing Polyurethane TU1208 Clear; SMC; Part No. X3; roll") -> Tubing Polyurethane TU1208 Clear; SMC; Part No. X3; roll | C17: =IFERROR(__xludf.DUMMYFUNCTION("""COMPUTED_VALUE"""),"O-12732-00") -> O-12732-00 | D17: =if(isna(vlookup(C17,'On Hand'!A:C,3,0)),"",vlookup(C17,'On Hand'!A:C,3,0))
A18: =IFERROR(__xludf.DUMMYFUNCTION("""COMPUTED_VALUE"""),"O-12733-00") -> O-12733-00 | B18: =IFERROR(__xludf.DUMMYFUNCTION("""COMPUTED_VALUE"""),"General - TU Polyurethane Tubing, TU1065C-100; SMC Pneumatics; -; 1 roll") -> General - TU Polyurethane Tubing, TU1065C-100; SMC Pneumatics; -; 1 roll | C18: =IFERROR(__xludf.DUMMYFUNCTION("""COMPUTED_VALUE"""),"O-12733-00") -> O-12733-00 | D18: =if(isna(vlookup(C18,'On Hand'!A:C,3,0)),"",vlookup(C18,'On Hand'!A:C,3,0))
A19: =IFERROR(__xludf.DUMMYFUNCTION("""COMPUTED_VALUE"""),"O-12734-00") -> O-12734-00 | B19: =IFERROR(__xludf.DUMMYFUNCTION("""COMPUTED_VALUE"""),"General - TU Polyurethane Tubing, TU0805C-100; SMC Pneumatics; -; 1 roll") -> General - TU Polyurethane Tubing, TU0805C-100; SMC Pneumatics; -; 1 roll | C19: =IFERROR(__xludf.DUMMYFUNCTION("""COMPUTED_VALUE"""),"O-12734-00") -> O-12734-00 | D19: =if(isna(vlookup(C19,'On Hand'!A:C,3,0)),"",vlookup(C19,'On Hand'!A:C,3,0))
A20: =IFERROR(__xludf.DUMMYFUNCTION("""COMPUTED_VALUE"""),"O-12735-00") -> O-12735-00 | B20: =IFERROR(__xludf.DUMMYFUNCTION("""COMPUTED_VALUE"""),"General - TU Polyurethane Tubing, TU0604C-100; SMC Pneumatics; -; 1 roll") -> General - TU Polyurethane Tubing, TU0604C-100; SMC Pneumatics; -; 1 roll | C20: =IFERROR(__xludf.DUMMYFUNCTION("""COMPUTED_VALUE"""),"O-12735-00") -> O-12735-00 | D20: =if(isna(vlookup(C20,'On Hand'!A:C,3,0)),"",vlookup(C20,'On Hand'!A:C,3,0))
A21: =IFERROR(__xludf.DUMMYFUNCTION("""COMPUTED_VALUE"""),"O-12736-00") -> O-12736-00 | B21: =IFERROR(__xludf.DUMMYFUNCTION("""COMPUTED_VALUE"""),"Tubing Polyurethane TU0425 Clear; ; ;") -> Tubing Polyurethane TU0425 Clear; ; ; | C21: =IFERROR(__xludf.DUMMYFUNCTION("""COMPUTED_VALUE"""),"O-12736-00") -> O-12736-00 | D21: =if(isna(vlookup(C21,'On Hand'!A:C,3,0)),"",vlookup(C21,'On Hand'!A:C,3,0))
A22: =IFERROR(__xludf.DUMMYFUNCTION("""COMPUTED_VALUE"""),"O-12868-00") -> O-12868-00 | B22: =IFERROR(__xludf.DUMMYFUNCTION("""COMPUTED_VALUE"""),"General - Emflon PFR membrane filter cartridge, 0.2 um sterilizing grade, 5-inch length, double-o-ring (silicone) with bayonet lock and flat end; Pall; AB05PFR2PVH4; 1 pcs") -> General - Emflon PFR membrane filter cartridge, 0.2 um sterilizing grade, 5-inch length, double-o-ring (silicone) with bayonet lock and flat end; Pall; AB05PFR2PVH4; 1 pcs | C22: =IFERROR(__xludf.DUMMYFUNCTION("""COMPUTED_VALUE"""),"O-12868-00") -> O-12868-00 | D22: =if(isna(vlookup(C22,'On Hand'!A:C,3,0)),"",vlookup(C22,'On Hand'!A:C,3,0))
A23: =IFERROR(__xludf.DUMMYFUNCTION("""COMPUTED_VALUE"""),"O-12918-00") -> O-12918-00 | B23: =IFERROR(__xludf.DUMMYFUNCTION("""COMPUTED_VALUE"""),"MARCHESINI MA 255 - p/n 322010 Nordson - Saturn precision Nozzle 200 mesh") -> MARCHESINI MA 255 - p/n 322010 Nordson - Saturn precision Nozzle 200 mesh | C23: =IFERROR(__xludf.DUMMYFUNCTION("""COMPUTED_VALUE"""),"O-12918-00") -> O-12918-00 | D23: =if(isna(vlookup(C23,'On Hand'!A:C,3,0)),"",vlookup(C23,'On Hand'!A:C,3,0))
A24: =IFERROR(__xludf.DUMMYFUNCTION("""COMPUTED_VALUE"""),"O-13062-00") -> O-13062-00 | B24: =IFERROR(__xludf.DUMMYFUNCTION("""COMPUTED_VALUE"""),"AUTOCLAVE Lab Mikro - PALL Emflon Filter 0,2um p/n C3PFRP1") -> AUTOCLAVE Lab Mikro - PALL Emflon Filter 0,2um p/n C3PFRP1 | C24: =IFERROR(__xludf.DUMMYFUNCTION("""COMPUTED_VALUE"""),"O-13062-00") -> O-13062-00 | D24: =if(isna(vlookup(C24,'On Hand'!A:C,3,0)),"",vlookup(C24,'On Hand'!A:C,3,0))
A25: =IFERROR(__xludf.DUMMYFUNCTION("""COMPUTED_VALUE"""),"O-13216-00") -> O-13216-00 | B25: =IFERROR(__xludf.DUMMYFUNCTION("""COMPUTED_VALUE"""),"Lubricant - Bechem Staroil G 320 Brown H1 @20 Liter/Pail") -> Lubricant - Bechem Staroil G 320 Brown H1 @20 Liter/Pail | C25: =IFERROR(__xludf.DUMMYFUNCTION("""COMPUTED_VALUE"""),"O-13216-00") -> O-13216-00 | D25: =if(isna(vlookup(C25,'On Hand'!A:C,3,0)),"",vlookup(C25,'On Hand'!A:C,3,0)) -> L
A26: =IFERROR(__xludf.DUMMYFUNCTION("""COMPUTED_VALUE"""),"O-13501-00") -> O-13501-00 | B26: =IFERROR(__xludf.DUMMYFUNCTION("""COMPUTED_VALUE"""),"General - Push-in T-connector, QST-12; Festo; 153132; 1 pcs") -> General - Push-in T-connector, QST-12; Festo; 153132; 1 pcs | C26: =IFERROR(__xludf.DUMMYFUNCTION("""COMPUTED_VALUE"""),"O-13501-00") -> O-13501-00 | D26: =if(isna(vlookup(C26,'On Hand'!A:C,3,0)),"",vlookup(C26,'On Hand'!A:C,3,0)) -> pc
A27: =IFERROR(__xludf.DUMMYFUNCTION("""COMPUTED_VALUE"""),"O-13505-00") -> O-13505-00 | B27: =IFERROR(__xludf.DUMMYFUNCTION("""COMPUTED_VALUE"""),"General - Push-in T-connector, QST-10; Festo; 153131; 1 pcs") -> General - Push-in T-connector, QST-10; Festo; 153131; 1 pcs | C27: =IFERROR(__xludf.DUMMYFUNCTION("""COMPUTED_VALUE"""),"O-13505-00") -> O-13505-00 | D27: =if(isna(vlookup(C27,'On Hand'!A:C,3,0)),"",vlookup(C27,'On Hand'!A:C,3,0)) -> pc
A28: =IFERROR(__xludf.DUMMYFUNCTION("""COMPUTED_VALUE"""),"O-13508-00") -> O-13508-00 | B28: =IFERROR(__xludf.DUMMYFUNCTION("""COMPUTED_VALUE"""),"Pneumatic Fitting - QS 8-6 FESTO P/N : - pc") -> Pneumatic Fitting - QS 8-6 FESTO P/N : - pc | C28: =IFERROR(__xludf.DUMMYFUNCTION("""COMPUTED_VALUE"""),"O-13508-00") -> O-13508-00 | D28: =if(isna(vlookup(C28,'On Hand'!A:C,3,0)),"",vlookup(C28,'On Hand'!A:C,3,0))
A29: =IFERROR(__xludf.DUMMYFUNCTION("""COMPUTED_VALUE"""),"O-13510-00") -> O-13510-00 | B29: =IFERROR(__xludf.DUMMYFUNCTION("""COMPUTED_VALUE"""),"Pneumatic Fitting - QS 12-10 FESTO P/N : - pc") -> Pneumatic Fitting - QS 12-10 FESTO P/N : - pc | C29: =IFERROR(__xludf.DUMMYFUNCTION("""COMPUTED_VALUE"""),"O-13510-00") -> O-13510-00 | D29: =if(isna(vlookup(C29,'On Hand'!A:C,3,0)),"",vlookup(C29,'On Hand'!A:C,3,0)) -> pc
A30: =IFERROR(__xludf.DUMMYFUNCTION("""COMPUTED_VALUE"""),"O-13521-00") -> O-13521-00 | B30: =IFERROR(__xludf.DUMMYFUNCTION("""COMPUTED_VALUE"""),"gasket 1 1/2"" / EPDM - P/N : - pc") -> gasket 1 1/2" / EPDM - P/N : - pc | C30: =IFERROR(__xludf.DUMMYFUNCTION("""COMPUTED_VALUE"""),"O-13521-00") -> O-13521-00 | D30: =if(isna(vlookup(C30,'On Hand'!A:C,3,0)),"",vlookup(C30,'On Hand'!A:C,3,0)) -> pc
A31: =IFERROR(__xludf.DUMMYFUNCTION("""COMPUTED_VALUE"""),"O-13522-00") -> O-13522-00 | B31: =IFERROR(__xludf.DUMMYFUNCTION("""COMPUTED_VALUE"""),"gasket 2"" / EPDM; ; ;") -> gasket 2" / EPDM; ; ; | C31: =IFERROR(__xludf.DUMMYFUNCTION("""COMPUTED_VALUE"""),"O-13522-00") -> O-13522-00 | D31: =if(isna(vlookup(C31,'On Hand'!A:C,3,0)),"",vlookup(C31,'On Hand'!A:C,3,0)) -> pc
A32: =IFERROR(__xludf.DUMMYFUNCTION("""COMPUTED_VALUE"""),"O-13617-00") -> O-13617-00 | B32: =IFERROR(__xludf.DUMMYFUNCTION("""COMPUTED_VALUE"""),"Marchesini MA255 Cartoning Machine - Flat Belt, 728 x 40 x 1 mm; Custom/Lokal; -; 1 unt") -> Marchesini MA255 Cartoning Machine - Flat Belt, 728 x 40 x 1 mm; Custom/Lokal; -; 1 unt | C32: =IFERROR(__xludf.DUMMYFUNCTION("""COMPUTED_VALUE"""),"O-13617-00") -> O-13617-00 | D32: =if(isna(vlookup(C32,'On Hand'!A:C,3,0)),"",vlookup(C32,'On Hand'!A:C,3,0))
A33: =IFERROR(__xludf.DUMMYFUNCTION("""COMPUTED_VALUE"""),"O-13799-00") -> O-13799-00 | B33: =IFERROR(__xludf.DUMMYFUNCTION("""COMPUTED_VALUE"""),"Carbon Vanes VT4.40 INTIDAYA DINAMIKA SEJATI, PT P/N : - pc") -> Carbon Vanes VT4.40 INTIDAYA DINAMIKA SEJATI, PT P/N : - pc | C33: =IFERROR(__xludf.DUMMYFUNCTION("""COMPUTED_VALUE"""),"O-13799-00") -> O-13799-00 | D33: =if(isna(vlookup(C33,'On Hand'!A:C,3,0)),"",vlookup(C33,'On Hand'!A:C,3,0))
A34: =IFERROR(__xludf.DUMMYFUNCTION("""COMPUTED_VALUE"""),"O-14022-00") -> O-14022-00 | B34: =IFERROR(__xludf.DUMMYFUNCTION("""COMPUTED_VALUE"""),"Valve Base SV-3-M5 Festo FESTO P/N : - pc") -> Valve Base SV-3-M5 Festo FESTO P/N : - pc | C34: =IFERROR(__xludf.DUMMYFUNCTION("""COMPUTED_VALUE"""),"O-14022-00") -> O-14022-00 | D34: =if(isna(vlookup(C34,'On Hand'!A:C,3,0)),"",vlookup(C34,'On Hand'!A:C,3,0)) -> pc
A35: =IFERROR(__xludf.DUMMYFUNCTION("""COMPUTED_VALUE"""),"O-14099-00") -> O-14099-00 | B35: =IFERROR(__xludf.DUMMYFUNCTION("""COMPUTED_VALUE"""),"Selang TS-25 (25x33) TOYOX P/N : - pc") -> Selang TS-25 (25x33) TOYOX P/N : - pc | C35: =IFERROR(__xludf.DUMMYFUNCTION("""COMPUTED_VALUE"""),"O-14099-00") -> O-14099-00 | D35: =if(isna(vlookup(C35,'On Hand'!A:C,3,0)),"",vlookup(C35,'On Hand'!A:C,3,0))
A36: =IFERROR(__xludf.DUMMYFUNCTION("""COMPUTED_VALUE"""),"O-14360-00") -> O-14360-00 | B36: =IFERROR(__xludf.DUMMYFUNCTION("""COMPUTED_VALUE"""),"Membran Valve EPDM PTFE DN 40 Gemu KRISNA DWI MITRA P/N : 600 40M5E-221 pc") -> Membran Valve EPDM PTFE DN 40 Gemu KRISNA DWI MITRA P/N : 600 40M5E-221 pc | C36: =IFERROR(__xludf.DUMMYFUNCTION("""COMPUTED_VALUE"""),"O-14360-00") -> O-14360-00 | D36: =if(isna(vlookup(C36,'On Hand'!A:C,3,0)),"",vlookup(C36,'On Hand'!A:C,3,0)) -> pc
A37: =IFERROR(__xludf.DUMMYFUNCTION("""COMPUTED_VALUE"""),"O-14363-00") -> O-14363-00 | B37: =IFERROR(__xludf.DUMMYFUNCTION("""COMPUTED_VALUE"""),"Membrane Diaphragm Valve EPDM PTFE DN 25 Gemu DUA BERLIAN PILAR P/N : 600 25M5E-221 pc") -> Membrane Diaphragm Valve EPDM PTFE DN 25 Gemu DUA BERLIAN PILAR P/N : 600 25M5E-221 pc | C37: =IFERROR(__xludf.DUMMYFUNCTION("""COMPUTED_VALUE"""),"O-14363-00") -> O-14363-00 | D37: =if(isna(vlookup(C37,'On Hand'!A:C,3,0)),"",vlookup(C37,'On Hand'!A:C,3,0)) -> pc
A38: =IFERROR(__xludf.DUMMYFUNCTION("""COMPUTED_VALUE"""),"O-14364-00") -> O-14364-00 | B38: =IFERROR(__xludf.DUMMYFUNCTION("""COMPUTED_VALUE"""),"Membrane Diaphragm Valve EPDM PTFE DN 50 p/n: 600 50M5E-221 Gemu; ; ;") -> Membrane Diaphragm Valve EPDM PTFE DN 50 p/n: 600 50M5E-221 Gemu; ; ; | C38: =IFERROR(__xludf.DUMMYFUNCTION("""COMPUTED_VALUE"""),"O-14364-00") -> O-14364-00 | D38: =if(isna(vlookup(C38,'On Hand'!A:C,3,0)),"",vlookup(C38,'On Hand'!A:C,3,0)) -> pc
A39: =IFERROR(__xludf.DUMMYFUNCTION("""COMPUTED_VALUE"""),"O-14449-00") -> O-14449-00 | B39: =IFERROR(__xludf.DUMMYFUNCTION("""COMPUTED_VALUE"""),"Isolator Glove Piercan 97800Y94/10 Material: Hypalon One Piece Fulled Dipped, White") -> Isolator Glove Piercan 97800Y94/10 Material: Hypalon One Piece Fulled Dipped, White | C39: =IFERROR(__xludf.DUMMYFUNCTION("""COMPUTED_VALUE"""),"O-14449-00") -> O-14449-00 | D39: =if(isna(vlookup(C39,'On Hand'!A:C,3,0)),"",vlookup(C39,'On Hand'!A:C,3,0))
A40: =IFERROR(__xludf.DUMMYFUNCTION("""COMPUTED_VALUE"""),"O-14510-00") -> O-14510-00 | B40: =IFERROR(__xludf.DUMMYFUNCTION("""COMPUTED_VALUE"""),"Speed Control AS2201F-02-08SA, SMC, , SINAR MUTIARA CAKRABUANA, PT P/N : - pc") -> Speed Control AS2201F-02-08SA, SMC, , SINAR MUTIARA CAKRABUANA, PT P/N : - pc | C40: =IFERROR(__xludf.DUMMYFUNCTION("""COMPUTED_VALUE"""),"O-14510-00") -> O-14510-00 | D40: =if(isna(vlookup(C40,'On Hand'!A:C,3,0)),"",vlookup(C40,'On Hand'!A:C,3,0)) -> pc
...

Sheet On Hand
A1: =IFERROR(__xludf.DUMMYFUNCTION("importrange(""1xC-uAlt1jPkVMJk3mS5BBJv2KXQQM32TIOguKnEzvGo"",""Inventory Tarikan Oracle!A:E"")"),"Item") -> Item | B1: =IFERROR(__xludf.DUMMYFUNCTION("""COMPUTED_VALUE"""),"Item Description") -> Item Description | C1: =IFERROR(__xludf.DUMMYFUNCTION("""COMPUTED_VALUE"""),"Primary UOM") -> Primary UOM | D1: =IFERROR(__xludf.DUMMYFUNCTION("""COMPUTED_VALUE"""),"On-hand") -> On-hand | E1: =IFERROR(__xludf.DUMMYFUNCTION("""COMPUTED_VALUE"""),"Lokator") -> Lokator
A2: =IFERROR(__xludf.DUMMYFUNCTION("""COMPUTED_VALUE"""),"O-19039-00") -> O-19039-00 | B2: =IFERROR(__xludf.DUMMYFUNCTION("""COMPUTED_VALUE"""),"General - Vent Filter Feed Water Tank KP 1 Emflon II Capsule 0.2 m; Pall; KA1V002PV3; 1 Pc") -> General - Vent Filter Feed Water Tank KP 1 Emflon II Capsule 0.2 m; Pall; KA1V002PV3; 1 Pc | C2: =IFERROR(__xludf.DUMMYFUNCTION("""COMPUTED_VALUE"""),"pc") -> pc | D2: =IFERROR(__xludf.DUMMYFUNCTION("""COMPUTED_VALUE"""),3.0) -> 3 | E2: =IFERROR(__xludf.DUMMYFUNCTION("""COMPUTED_VALUE"""),"E-3") -> E-3
A3: =IFERROR(__xludf.DUMMYFUNCTION("""COMPUTED_VALUE"""),"O-14639-00") -> O-14639-00 | B3: =IFERROR(__xludf.DUMMYFUNCTION("""COMPUTED_VALUE"""),"General - EPDM Gasket for Ferrule dia. 1/2""; -; -; 1 pc") -> General - EPDM Gasket for Ferrule dia. 1/2"; -; -; 1 pc | C3: =IFERROR(__xludf.DUMMYFUNCTION("""COMPUTED_VALUE"""),"pc") -> pc | D3: =IFERROR(__xludf.DUMMYFUNCTION("""COMPUTED_VALUE"""),16.0) -> 16 | E3: =IFERROR(__xludf.DUMMYFUNCTION("""COMPUTED_VALUE"""),"M-2") -> M-2
A4: =IFERROR(__xludf.DUMMYFUNCTION("""COMPUTED_VALUE"""),"O-14642-00") -> O-14642-00 | B4: =IFERROR(__xludf.DUMMYFUNCTION("""COMPUTED_VALUE"""),"General - Silicone Gasket for Ferrule dia. 2,5""; -; -; 1 Pc") -> General - Silicone Gasket for Ferrule dia. 2,5"; -; -; 1 Pc | C4: =IFERROR(__xludf.DUMMYFUNCTION("""COMPUTED_VALUE"""),"pc") -> pc | D4: =IFERROR(__xludf.DUMMYFUNCTION("""COMPUTED_VALUE"""),6.0) -> 6 | E4: =IFERROR(__xludf.DUMMYFUNCTION("""COMPUTED_VALUE"""),"M3") -> M3
A5: =IFERROR(__xludf.DUMMYFUNCTION("""COMPUTED_VALUE"""),"O-14644-00") -> O-14644-00 | B5: =IFERROR(__xludf.DUMMYFUNCTION("""COMPUTED_VALUE"""),"General - Silicone Gasket for Ferrule dia. 4""; -; -; 1 Pc") -> General - Silicone Gasket for Ferrule dia. 4"; -; -; 1 Pc | C5: =IFERROR(__xludf.DUMMYFUNCTION("""COMPUTED_VALUE"""),"pc") -> pc | D5: =IFERROR(__xludf.DUMMYFUNCTION("""COMPUTED_VALUE"""),8.0) -> 8 | E5: =IFERROR(__xludf.DUMMYFUNCTION("""COMPUTED_VALUE"""),"M3") -> M3
A6: =IFERROR(__xludf.DUMMYFUNCTION("""COMPUTED_VALUE"""),"O-11173-00") -> O-11173-00 | B6: =IFERROR(__xludf.DUMMYFUNCTION("""COMPUTED_VALUE"""),"General - Bearing 6208; SKF; -; 1 pcs") -> General - Bearing 6208; SKF; -; 1 pcs | C6: =IFERROR(__xludf.DUMMYFUNCTION("""COMPUTED_VALUE"""),"pc") -> pc | D6: =IFERROR(__xludf.DUMMYFUNCTION("""COMPUTED_VALUE"""),8.0) -> 8 | E6: =IFERROR(__xludf.DUMMYFUNCTION("""COMPUTED_VALUE"""),"G-2") -> G-2
A7: =IFERROR(__xludf.DUMMYFUNCTION("""COMPUTED_VALUE"""),"O-18694-00") -> O-18694-00 | B7: =IFERROR(__xludf.DUMMYFUNCTION("""COMPUTED_VALUE"""),"Autoclave Fedegari FVA2/A1 NB2963AT - DN22 Blind CAP P/N: PM102748; ; ;") -> Autoclave Fedegari FVA2/A1 NB2963AT - DN22 Blind CAP P/N: PM102748; ; ; | C7: =IFERROR(__xludf.DUMMYFUNCTION("""COMPUTED_VALUE"""),"pc") -> pc | D7: =IFERROR(__xludf.DUMMYFUNCTION("""COMPUTED_VALUE"""),2.0) -> 2 | E7: =IFERROR(__xludf.DUMMYFUNCTION("""COMPUTED_VALUE"""),"E-3-5") -> E-3-5
A8: =IFERROR(__xludf.DUMMYFUNCTION("""COMPUTED_VALUE"""),"O-17073-00") -> O-17073-00 | B8: =IFERROR(__xludf.DUMMYFUNCTION("""COMPUTED_VALUE"""),"Capping VCM210 - Plate Capping; Custom/Lokal; -; 1 Pc") -> Capping VCM210 - Plate Capping; Custom/Lokal; -; 1 Pc | C8: =IFERROR(__xludf.DUMMYFUNCTION("""COMPUTED_VALUE"""),"pc") -> pc | D8: =IFERROR(__xludf.DUMMYFUNCTION("""COMPUTED_VALUE"""),2.0) -> 2 | E8: =IFERROR(__xludf.DUMMYFUNCTION("""COMPUTED_VALUE"""),"A-1-7") -> A-1-7
A9: =IFERROR(__xludf.DUMMYFUNCTION("""COMPUTED_VALUE"""),"P-13368-00") -> P-13368-00 | B9: =IFERROR(__xludf.DUMMYFUNCTION("""COMPUTED_VALUE"""),"PS300X Air Flow Switch; Regin Control; ;") -> PS300X Air Flow Switch; Regin Control; ; | C9: =IFERROR(__xludf.DUMMYFUNCTION("""COMPUTED_VALUE"""),"unt") -> unt | D9: =IFERROR(__xludf.DUMMYFUNCTION("""COMPUTED_VALUE"""),1.0) -> 1 | E9: =IFERROR(__xludf.DUMMYFUNCTION("""COMPUTED_VALUE"""),"L3") -> L3
A10: =IFERROR(__xludf.DUMMYFUNCTION("""COMPUTED_VALUE"""),"O-18447-00") -> O-18447-00 | B10: =IFERROR(__xludf.DUMMYFUNCTION("""COMPUTED_VALUE"""),"General - Silicone Guide Outfeed; Custom/Lokal; -; 1 Pc") -> General - Silicone Guide Outfeed; Custom/Lokal; -; 1 Pc | C10: =IFERROR(__xludf.DUMMYFUNCTION("""COMPUTED_VALUE"""),"pc") -> pc | D10: =IFERROR(__xludf.DUMMYFUNCTION("""COMPUTED_VALUE"""),1.0) -> 1
A11: =IFERROR(__xludf.DUMMYFUNCTION("""COMPUTED_VALUE"""),"O-52702-00") -> O-52702-00 | B11: =IFERROR(__xludf.DUMMYFUNCTION("""COMPUTED_VALUE"""),"Autoclave Machine - AQUATEC PUMP 8883-2L01-X704 230-50; Fedegari; CF030259; 1 Pc") -> Autoclave Machine - AQUATEC PUMP 8883-2L01-X704 230-50; Fedegari; CF030259; 1 Pc | C11: =IFERROR(__xludf.DUMMYFUNCTION("""COMPUTED_VALUE"""),"pc") -> pc | D11: =IFERROR(__xludf.DUMMYFUNCTION("""COMPUTED_VALUE"""),1.0) -> 1 | E11: =IFERROR(__xludf.DUMMYFUNCTION("""COMPUTED_VALUE"""),"E-3-7") -> E-3-7
A12: =IFERROR(__xludf.DUMMYFUNCTION("""COMPUTED_VALUE"""),"O-15490-00") -> O-15490-00 | B12: =IFERROR(__xludf.DUMMYFUNCTION("""COMPUTED_VALUE"""),"B63 Brand : Optibelt / Bando Merah; Optibelt; ;") -> B63 Brand : Optibelt / Bando Merah; Optibelt; ; | C12: =IFERROR(__xludf.DUMMYFUNCTION("""COMPUTED_VALUE"""),"pc") -> pc | D12: =IFERROR(__xludf.DUMMYFUNCTION("""COMPUTED_VALUE"""),4.0) -> 4 | E12: =IFERROR(__xludf.DUMMYFUNCTION("""COMPUTED_VALUE"""),"L2") -> L2
A13: =IFERROR(__xludf.DUMMYFUNCTION("""COMPUTED_VALUE"""),"P-15351-00") -> P-15351-00 | B13: =IFERROR(__xludf.DUMMYFUNCTION("""COMPUTED_VALUE"""),"General - Plastic Tubing, PUN-10X1,5-BL; Festo; 159668; 1 m") -> General - Plastic Tubing, PUN-10X1,5-BL; Festo; 159668; 1 m | C13: =IFERROR(__xludf.DUMMYFUNCTION("""COMPUTED_VALUE"""),"pc") -> pc | D13: =IFERROR(__xludf.DUMMYFUNCTION("""COMPUTED_VALUE"""),44.0) -> 44 | E13: =IFERROR(__xludf.DUMMYFUNCTION("""COMPUTED_VALUE"""),"Atas Flammable") -> Atas Flammable
A14: =IFERROR(__xludf.DUMMYFUNCTION("""COMPUTED_VALUE"""),"Q-60006-00") -> Q-60006-00 | B14: =IFERROR(__xludf.DUMMYFUNCTION("""COMPUTED_VALUE"""),"Dempul Kayu;Sanpolac;;pack size per 1 kg pack") -> Dempul Kayu;Sanpolac;;pack size per 1 kg pack | C14: =IFERROR(__xludf.DUMMYFUNCTION("""COMPUTED_VALUE"""),"Kg") -> Kg | D14: =IFERROR(__xludf.DUMMYFUNCTION("""COMPUTED_VALUE"""),2.0) -> 2 | E14: =IFERROR(__xludf.DUMMYFUNCTION("""COMPUTED_VALUE"""),"Flammable") -> Flammable
A15: =IFERROR(__xludf.DUMMYFUNCTION("""COMPUTED_VALUE"""),"P-17260-00") -> P-17260-00 | B15: =IFERROR(__xludf.DUMMYFUNCTION("""COMPUTED_VALUE"""),"General - Oil seal G. size. 14 x 20 x 3 mm; No Brand; -; 1 pc") -> General - Oil seal G. size. 14 x 20 x 3 mm; No Brand; -; 1 pc | C15: =IFERROR(__xludf.DUMMYFUNCTION("""COMPUTED_VALUE"""),"pc") -> pc | D15: =IFERROR(__xludf.DUMMYFUNCTION("""COMPUTED_VALUE"""),5.0) -> 5 | E15: =IFERROR(__xludf.DUMMYFUNCTION("""COMPUTED_VALUE"""),"E-3-1C") -> E-3-1C
A16: =IFERROR(__xludf.DUMMYFUNCTION("""COMPUTED_VALUE"""),"O-19379-00") -> O-19379-00 | B16: =IFERROR(__xludf.DUMMYFUNCTION("""COMPUTED_VALUE"""),"General - Oli Refrigeration; Xaerus; XR 534-46; 1 Pc") -> General - Oli Refrigeration; Xaerus; XR 534-46; 1 Pc | C16: =IFERROR(__xludf.DUMMYFUNCTION("""COMPUTED_VALUE"""),"Can") -> Can | D16: =IFERROR(__xludf.DUMMYFUNCTION("""COMPUTED_VALUE"""),10.0) -> 10 | E16: =IFERROR(__xludf.DUMMYFUNCTION("""COMPUTED_VALUE"""),"D-4-1") -> D-4-1
A17: =IFERROR(__xludf.DUMMYFUNCTION("""COMPUTED_VALUE"""),"O-18560-00") -> O-18560-00 | B17: =IFERROR(__xludf.DUMMYFUNCTION("""COMPUTED_VALUE"""),"FD Lyofast 10 - hydraulically Balanced Valve (EB02-00595); Dana; M8596N002; 1 pc") -> FD Lyofast 10 - hydraulically Balanced Valve (EB02-00595); Dana; M8596N002; 1 pc | C17: =IFERROR(__xludf.DUMMYFUNCTION("""COMPUTED_VALUE"""),"pc") -> pc | D17: =IFERROR(__xludf.DUMMYFUNCTION("""COMPUTED_VALUE"""),1.0) -> 1 | E17: =IFERROR(__xludf.DUMMYFUNCTION("""COMPUTED_VALUE"""),"D-2") -> D-2
A18: =IFERROR(__xludf.DUMMYFUNCTION("""COMPUTED_VALUE"""),"O-21430-00") -> O-21430-00 | B18: =IFERROR(__xludf.DUMMYFUNCTION("""COMPUTED_VALUE"""),"Blister TR100LT - Teflon Forming 568 ukuran 11.5x19; Custom/Lokal; ; 1 Pc") -> Blister TR100LT - Teflon Forming 568 ukuran 11.5x19; Custom/Lokal; ; 1 Pc | C18: =IFERROR(__xludf.DUMMYFUNCTION("""COMPUTED_VALUE"""),"pc") -> pc | D18: =IFERROR(__xludf.DUMMYFUNCTION("""COMPUTED_VALUE"""),30.0) -> 30 | E18: =IFERROR(__xludf.DUMMYFUNCTION("""COMPUTED_VALUE"""),"-") -> -
A19: =IFERROR(__xludf.DUMMYFUNCTION("""COMPUTED_VALUE"""),"O-14510-00") -> O-14510-00 | B19: =IFERROR(__xludf.DUMMYFUNCTION("""COMPUTED_VALUE"""),"General - Flow Control With Fitting, AS2201F-02-08SA; SMC Pneumatics; -; 1 pcs") -> General - Flow Control With Fitting, AS2201F-02-08SA; SMC Pneumatics; -; 1 pcs | C19: =IFERROR(__xludf.DUMMYFUNCTION("""COMPUTED_VALUE"""),"pc") -> pc | D19: =IFERROR(__xludf.DUMMYFUNCTION("""COMPUTED_VALUE"""),4.0) -> 4 | E19: =IFERROR(__xludf.DUMMYFUNCTION("""COMPUTED_VALUE"""),"E-4-1C") -> E-4-1C
A20: =IFERROR(__xludf.DUMMYFUNCTION("""COMPUTED_VALUE"""),"O-17313-00") -> O-17313-00 | B20: =IFERROR(__xludf.DUMMYFUNCTION("""COMPUTED_VALUE"""),"General - Breathing Circuit Filter; PALL; BB50T; 1 Pc") -> General - Breathing Circuit Filter; PALL; BB50T; 1 Pc | C20: =IFERROR(__xludf.DUMMYFUNCTION("""COMPUTED_VALUE"""),"pc") -> pc | D20: =IFERROR(__xludf.DUMMYFUNCTION("""COMPUTED_VALUE"""),38.0) -> 38 | E20: =IFERROR(__xludf.DUMMYFUNCTION("""COMPUTED_VALUE"""),"F2") -> F2
A21: =IFERROR(__xludf.DUMMYFUNCTION("""COMPUTED_VALUE"""),"P-17360-00") -> P-17360-00 | B21: =IFERROR(__xludf.DUMMYFUNCTION("""COMPUTED_VALUE"""),"General - O-ring EPDM 22.5 x 15.5 x 3.5 mm; No Brand; -; 1 pc") -> General - O-ring EPDM 22.5 x 15.5 x 3.5 mm; No Brand; -; 1 pc | C21: =IFERROR(__xludf.DUMMYFUNCTION("""COMPUTED_VALUE"""),"pc") -> pc | D21: =IFERROR(__xludf.DUMMYFUNCTION("""COMPUTED_VALUE"""),4.0) -> 4 | E21: =IFERROR(__xludf.DUMMYFUNCTION("""COMPUTED_VALUE"""),"E-3-5") -> E-3-5
A22: =IFERROR(__xludf.DUMMYFUNCTION("""COMPUTED_VALUE"""),"P-12083-00") -> P-12083-00 | B22: =IFERROR(__xludf.DUMMYFUNCTION("""COMPUTED_VALUE"""),"General - Clamp Selang, SS, 1/2""; Tridon; -; 1 pcs") -> General - Clamp Selang, SS, 1/2"; Tridon; -; 1 pcs | C22: =IFERROR(__xludf.DUMMYFUNCTION("""COMPUTED_VALUE"""),"pc") -> pc | D22: =IFERROR(__xludf.DUMMYFUNCTION("""COMPUTED_VALUE"""),3.0) -> 3
A23: =IFERROR(__xludf.DUMMYFUNCTION("""COMPUTED_VALUE"""),"P-18470-00") -> P-18470-00 | B23: =IFERROR(__xludf.DUMMYFUNCTION("""COMPUTED_VALUE"""),"General - HXNHFFLT-SUS-M5-10; Misumi; -; 1 Pc") -> General - HXNHFFLT-SUS-M5-10; Misumi; -; 1 Pc | C23: =IFERROR(__xludf.DUMMYFUNCTION("""COMPUTED_VALUE"""),"pc") -> pc | D23: =IFERROR(__xludf.DUMMYFUNCTION("""COMPUTED_VALUE"""),22.0) -> 22 | E23: =IFERROR(__xludf.DUMMYFUNCTION("""COMPUTED_VALUE"""),"B-2-1B") -> B-2-1B
A24: =IFERROR(__xludf.DUMMYFUNCTION("""COMPUTED_VALUE"""),"O-51850-00") -> O-51850-00 | B24: =IFERROR(__xludf.DUMMYFUNCTION("""COMPUTED_VALUE"""),"General - Power Supply 220 VAC 12 VDC, 3 Ampere; -; -; 1 Pc") -> General - Power Supply 220 VAC 12 VDC, 3 Ampere; -; -; 1 Pc | C24: =IFERROR(__xludf.DUMMYFUNCTION("""COMPUTED_VALUE"""),"pc") -> pc | D24: =IFERROR(__xludf.DUMMYFUNCTION("""COMPUTED_VALUE"""),3.0) -> 3 | E24: =IFERROR(__xludf.DUMMYFUNCTION("""COMPUTED_VALUE"""),"L3") -> L3
A25: =IFERROR(__xludf.DUMMYFUNCTION("""COMPUTED_VALUE"""),"P-51812-00") -> P-51812-00 | B25: =IFERROR(__xludf.DUMMYFUNCTION("""COMPUTED_VALUE"""),"Indoor Sirene; ; ;") -> Indoor Sirene; ; ; | C25: =IFERROR(__xludf.DUMMYFUNCTION("""COMPUTED_VALUE"""),"unt") -> unt | D25: =IFERROR(__xludf.DUMMYFUNCTION("""COMPUTED_VALUE"""),1.0) -> 1 | E25: =IFERROR(__xludf.DUMMYFUNCTION("""COMPUTED_VALUE"""),"F-2-3A") -> F-2-3A
A26: =IFERROR(__xludf.DUMMYFUNCTION("""COMPUTED_VALUE"""),"P-19569-00") -> P-19569-00 | B26: =IFERROR(__xludf.DUMMYFUNCTION("""COMPUTED_VALUE"""),"General - Sanitary Diaphragma Pressure Gauge, SS 304, dia 4inch, Range 0-10 Bar; SPV; TTXX00XX0180; 1 pcs") -> General - Sanitary Diaphragma Pressure Gauge, SS 304, dia 4inch, Range 0-10 Bar; SPV; TTXX00XX0180; 1 pcs | C26: =IFERROR(__xludf.DUMMYFUNCTION("""COMPUTED_VALUE"""),"pc") -> pc | D26: =IFERROR(__xludf.DUMMYFUNCTION("""COMPUTED_VALUE"""),2.0) -> 2 | E26: =IFERROR(__xludf.DUMMYFUNCTION("""COMPUTED_VALUE"""),"L-4") -> L-4
A27: =IFERROR(__xludf.DUMMYFUNCTION("""COMPUTED_VALUE"""),"P-18279-00") -> P-18279-00 | B27: =IFERROR(__xludf.DUMMYFUNCTION("""COMPUTED_VALUE"""),"General - Freon R134A; Refrigerant; -; 1 pc") -> General - Freon R134A; Refrigerant; -; 1 pc | C27: =IFERROR(__xludf.DUMMYFUNCTION("""COMPUTED_VALUE"""),"Can") -> Can | D27: =IFERROR(__xludf.DUMMYFUNCTION("""COMPUTED_VALUE"""),1.0) -> 1 | E27: =IFERROR(__xludf.DUMMYFUNCTION("""COMPUTED_VALUE"""),"N1") -> N1
A28: =IFERROR(__xludf.DUMMYFUNCTION("""COMPUTED_VALUE"""),"O-20897-00") -> O-20897-00 | B28: =IFERROR(__xludf.DUMMYFUNCTION("""COMPUTED_VALUE"""),"Capping VCM200 - Oring Silicone 2.5 x 30.50 x 30.50; Custom/Lokal; -; 1 Pc") -> Capping VCM200 - Oring Silicone 2.5 x 30.50 x 30.50; Custom/Lokal; -; 1 Pc | C28: =IFERROR(__xludf.DUMMYFUNCTION("""COMPUTED_VALUE"""),"pc") -> pc | D28: =IFERROR(__xludf.DUMMYFUNCTION("""COMPUTED_VALUE"""),20.0) -> 20 | E28: =IFERROR(__xludf.DUMMYFUNCTION("""COMPUTED_VALUE"""),"A-1-1") -> A-1-1
A29: =IFERROR(__xludf.DUMMYFUNCTION("""COMPUTED_VALUE"""),"T-20146-00") -> T-20146-00 | B29: =IFERROR(__xludf.DUMMYFUNCTION("""COMPUTED_VALUE"""),"Inlab Cable MultiPin-BNC/RCA 1.2m cat no 30281896; Mettler Toledo; c/n 30281896; 1 pc") -> Inlab Cable MultiPin-BNC/RCA 1.2m cat no 30281896; Mettler Toledo; c/n 30281896; 1 pc | C29: =IFERROR(__xludf.DUMMYFUNCTION("""COMPUTED_VALUE"""),"pc") -> pc | D29: =IFERROR(__xludf.DUMMYFUNCTION("""COMPUTED_VALUE"""),1.0) -> 1 | E29: =IFERROR(__xludf.DUMMYFUNCTION("""COMPUTED_VALUE"""),"F-2-4B") -> F-2-4B
A30: =IFERROR(__xludf.DUMMYFUNCTION("""COMPUTED_VALUE"""),"Q-10572-00") -> Q-10572-00 | B30: =IFERROR(__xludf.DUMMYFUNCTION("""COMPUTED_VALUE"""),"Lampu LED Tube TL T8 16W 1200 mm;Philips;;pack size per pcs") -> Lampu LED Tube TL T8 16W 1200 mm;Philips;;pack size per pcs | C30: =IFERROR(__xludf.DUMMYFUNCTION("""COMPUTED_VALUE"""),"pc") -> pc | D30: =IFERROR(__xludf.DUMMYFUNCTION("""COMPUTED_VALUE"""),4.0) -> 4 | E30: =IFERROR(__xludf.DUMMYFUNCTION("""COMPUTED_VALUE"""),"O4") -> O4
A31: =IFERROR(__xludf.DUMMYFUNCTION("""COMPUTED_VALUE"""),"P-53293-00") -> P-53293-00 | B31: =IFERROR(__xludf.DUMMYFUNCTION("""COMPUTED_VALUE"""),"General - Lampu Emergency TL LED 16W Waterproof IP65; Briliant; -; 1 pc") -> General - Lampu Emergency TL LED 16W Waterproof IP65; Briliant; -; 1 pc | C31: =IFERROR(__xludf.DUMMYFUNCTION("""COMPUTED_VALUE"""),"pc") -> pc | D31: =IFERROR(__xludf.DUMMYFUNCTION("""COMPUTED_VALUE"""),11.0) -> 11
A32: =IFERROR(__xludf.DUMMYFUNCTION("""COMPUTED_VALUE"""),"P-51857-00") -> P-51857-00 | B32: =IFERROR(__xludf.DUMMYFUNCTION("""COMPUTED_VALUE"""),"General - Contact Block SA-CBM; Autonics; -; 1 pc") -> General - Contact Block SA-CBM; Autonics; -; 1 pc | C32: =IFERROR(__xludf.DUMMYFUNCTION("""COMPUTED_VALUE"""),"pc") -> pc | D32: =IFERROR(__xludf.DUMMYFUNCTION("""COMPUTED_VALUE"""),2.0) -> 2 | E32: =IFERROR(__xludf.DUMMYFUNCTION("""COMPUTED_VALUE"""),"F-2-2D") -> F-2-2D
A33: =IFERROR(__xludf.DUMMYFUNCTION("""COMPUTED_VALUE"""),"P-10398-00") -> P-10398-00 | B33: =IFERROR(__xludf.DUMMYFUNCTION("""COMPUTED_VALUE"""),"General - Ball Valve SS316 1/2inch 1000 WOG; Sankyo; -; 1 Pc") -> General - Ball Valve SS316 1/2inch 1000 WOG; Sankyo; -; 1 Pc | C33: =IFERROR(__xludf.DUMMYFUNCTION("""COMPUTED_VALUE"""),"pc") -> pc | D33: =IFERROR(__xludf.DUMMYFUNCTION("""COMPUTED_VALUE"""),1.0) -> 1 | E33: =IFERROR(__xludf.DUMMYFUNCTION("""COMPUTED_VALUE"""),"F-1") -> F-1
A34: =IFERROR(__xludf.DUMMYFUNCTION("""COMPUTED_VALUE"""),"P-52975-00") -> P-52975-00 | B34: =IFERROR(__xludf.DUMMYFUNCTION("""COMPUTED_VALUE"""),"General - Limit Switch IP65; EWIG; E8108; 1 pc") -> General - Limit Switch IP65; EWIG; E8108; 1 pc | C34: =IFERROR(__xludf.DUMMYFUNCTION("""COMPUTED_VALUE"""),"pc") -> pc | D34: =IFERROR(__xludf.DUMMYFUNCTION("""COMPUTED_VALUE"""),3.0) -> 3 | E34: =IFERROR(__xludf.DUMMYFUNCTION("""COMPUTED_VALUE"""),"A-4-10A") -> A-4-10A
A35: =IFERROR(__xludf.DUMMYFUNCTION("""COMPUTED_VALUE"""),"O-54167-00") -> O-54167-00 | B35: =IFERROR(__xludf.DUMMYFUNCTION("""COMPUTED_VALUE"""),"General - Connector Cable CLD408-5; Autonics; H7950000609; 1 Pc") -> General - Connector Cable CLD408-5; Autonics; H7950000609; 1 Pc | C35: =IFERROR(__xludf.DUMMYFUNCTION("""COMPUTED_VALUE"""),"pc") -> pc | D35: =IFERROR(__xludf.DUMMYFUNCTION("""COMPUTED_VALUE"""),2.0) -> 2 | E35: =IFERROR(__xludf.DUMMYFUNCTION("""COMPUTED_VALUE"""),"B-2-3") -> B-2-3
A36: =IFERROR(__xludf.DUMMYFUNCTION("""COMPUTED_VALUE"""),"P-50138-00") -> P-50138-00 | B36: =IFERROR(__xludf.DUMMYFUNCTION("""COMPUTED_VALUE"""),"Battery Lithium / Buffer TL-2150 size 1/2 AA") -> Battery Lithium / Buffer TL-2150 size 1/2 AA | C36: =IFERROR(__xludf.DUMMYFUNCTION("""COMPUTED_VALUE"""),"pc") -> pc | D36: =IFERROR(__xludf.DUMMYFUNCTION("""COMPUTED_VALUE"""),6.0) -> 6 | E36: =IFERROR(__xludf.DUMMYFUNCTION("""COMPUTED_VALUE"""),"G-3") -> G-3
A37: =IFERROR(__xludf.DUMMYFUNCTION("""COMPUTED_VALUE"""),"P-13754-00") -> P-13754-00 | B37: =IFERROR(__xludf.DUMMYFUNCTION("""COMPUTED_VALUE"""),"General - Electromotoric actuator, 400 N, 5.5 mm, AC 24 V, DC 0...10 V; Siemens; SQS65; 1 pcs") -> General - Electromotoric actuator, 400 N, 5.5 mm, AC 24 V, DC 0...10 V; Siemens; SQS65; 1 pcs | C37: =IFERROR(__xludf.DUMMYFUNCTION("""COMPUTED_VALUE"""),"unt") -> unt | D37: =IFERROR(__xludf.DUMMYFUNCTION("""COMPUTED_VALUE"""),1.0) -> 1 | E37: =IFERROR(__xludf.DUMMYFUNCTION("""COMPUTED_VALUE"""),"L-3") -> L-3
A38: =IFERROR(__xludf.DUMMYFUNCTION("""COMPUTED_VALUE"""),"O-14617-00") -> O-14617-00 | B38: =IFERROR(__xludf.DUMMYFUNCTION("""COMPUTED_VALUE"""),"General - Solenoid valve 2/2 ways NC 4,5mm; Steriline; 28582; 1 Pc") -> General - Solenoid valve 2/2 ways NC 4,5mm; Steriline; 28582; 1 Pc | C38: =IFERROR(__xludf.DUMMYFUNCTION("""COMPUTED_VALUE"""),"unt") -> unt | D38: =IFERROR(__xludf.DUMMYFUNCTION("""COMPUTED_VALUE"""),2.0) -> 2 | E38: =IFERROR(__xludf.DUMMYFUNCTION("""COMPUTED_VALUE"""),"B-2-4C") -> B-2-4C
A39: =IFERROR(__xludf.DUMMYFUNCTION("""COMPUTED_VALUE"""),"P-14974-00") -> P-14974-00 | B39: =IFERROR(__xludf.DUMMYFUNCTION("""COMPUTED_VALUE"""),"General - Socket AW 2 1/2inch; Rucika; -; 1 pcs") -> General - Socket AW 2 1/2inch; Rucika; -; 1 pcs | C39: =IFERROR(__xludf.DUMMYFUNCTION("""COMPUTED_VALUE"""),"pc") -> pc | D39: =IFERROR(__xludf.DUMMYFUNCTION("""COMPUTED_VALUE"""),3.0) -> 3 | E39: =IFERROR(__xludf.DUMMYFUNCTION("""COMPUTED_VALUE"""),"F3") -> F3
A40: =IFERROR(__xludf.DUMMYFUNCTION("""COMPUTED_VALUE"""),"P-19659-00") -> P-19659-00 | B40: =IFERROR(__xludf.DUMMYFUNCTION("""COMPUTED_VALUE"""),"General - Dop, PVC AW, 3/4""; Rucika; -; 1 pc") -> General - Dop, PVC AW, 3/4"; Rucika; -; 1 pc | C40: =IFERROR(__xludf.DUMMYFUNCTION("""COMPUTED_VALUE"""),"pc") -> pc | D40: =IFERROR(__xludf.DUMMYFUNCTION("""COMPUTED_VALUE"""),4.0) -> 4
...
